01/10/13 23:41:40 INFO: * Running on http://0.0.0.0:5692/
01/10/13 23:46:23 INFO:192.168.1.28 - - [10/Jan/2013 23:46:23] "GET /command/?command=enumerate_plugins HTTP/1.1" 200 -
01/10/13 23:47:13 INFO:192.168.1.26 - - [10/Jan/2013 23:47:13] "GET /command/?command=enumerate_plugins HTTP/1.0" 200 -
01/10/13 23:50:47 INFO:192.168.1.26 - - [10/Jan/2013 23:50:47] "GET /?command=enumerate_plugins HTTP/1.1" 200 -
01/10/13 23:51:18 INFO:127.0.0.1 - - [10/Jan/2013 23:51:18] "GET /?command=enumerate_plugins HTTP/1.1" 200 -
01/10/13 23:52:28 INFO:127.0.0.1 - - [10/Jan/2013 23:52:28] "GET /?command=enumerate_plugins HTTP/1.1" 200 -
01/11/13 00:01:08 WARNING:User attempted to restart, var/ncpa_listener.pid still exists, exiting.
01/11/13 00:01:15 INFO: * Running on http://0.0.0.0:5692/
01/11/13 00:01:21 ERROR:Exception on /config [GET]
Traceback (most recent call last):
  File "/usr/lib/python2.6/site-packages/flask/app.py", line 1687, in wsgi_app
    response = self.full_dispatch_request()
  File "/usr/lib/python2.6/site-packages/flask/app.py", line 1360, in full_dispatch_request
    rv = self.handle_user_exception(e)
  File "/usr/lib/python2.6/site-packages/flask/app.py", line 1358, in full_dispatch_request
    rv = self.dispatch_request()
  File "/usr/lib/python2.6/site-packages/flask/app.py", line 1344, in dispatch_request
    return self.view_functions[rule.endpoint](**req.view_args)
  File "/tmp/ncpa/agent/listener/server.py", line 36, in config
    logging.exception(e)
NameError: global name 'e' is not defined
01/11/13 00:01:21 INFO:192.168.1.28 - - [11/Jan/2013 00:01:21] "GET /config HTTP/1.1" 500 -
01/11/13 00:01:21 ERROR:Error on request:
Traceback (most recent call last):
  File "/usr/lib/python2.6/site-packages/werkzeug/serving.py", line 159, in run_wsgi
    execute(app)
  File "/usr/lib/python2.6/site-packages/werkzeug/serving.py", line 146, in execute
    application_iter = app(environ, start_response)
  File "/usr/lib/python2.6/site-packages/flask/app.py", line 1701, in __call__
    return self.wsgi_app(environ, start_response)
  File "/usr/lib/python2.6/site-packages/flask/app.py", line 1689, in wsgi_app
    response = self.make_response(self.handle_exception(e))
  File "/usr/lib/python2.6/site-packages/flask/app.py", line 1293, in handle_exception
    return handler(e)
TypeError: error() takes no arguments (1 given)
01/11/13 00:02:26 INFO: * Running on http://0.0.0.0:5692/
01/11/13 00:02:30 ERROR:Exception on /config [GET]
Traceback (most recent call last):
  File "/usr/lib/python2.6/site-packages/flask/app.py", line 1687, in wsgi_app
    response = self.full_dispatch_request()
  File "/usr/lib/python2.6/site-packages/flask/app.py", line 1360, in full_dispatch_request
    rv = self.handle_user_exception(e)
  File "/usr/lib/python2.6/site-packages/flask/app.py", line 1358, in full_dispatch_request
    rv = self.dispatch_request()
  File "/usr/lib/python2.6/site-packages/flask/app.py", line 1344, in dispatch_request
    return self.view_functions[rule.endpoint](**req.view_args)
  File "/tmp/ncpa/agent/listener/server.py", line 38, in config
    logging.exception(e)
NameError: global name 'e' is not defined
01/11/13 00:02:30 INFO:192.168.1.28 - - [11/Jan/2013 00:02:30] "GET /config HTTP/1.1" 500 -
01/11/13 00:02:30 ERROR:Error on request:
Traceback (most recent call last):
  File "/usr/lib/python2.6/site-packages/werkzeug/serving.py", line 159, in run_wsgi
    execute(app)
  File "/usr/lib/python2.6/site-packages/werkzeug/serving.py", line 146, in execute
    application_iter = app(environ, start_response)
  File "/usr/lib/python2.6/site-packages/flask/app.py", line 1701, in __call__
    return self.wsgi_app(environ, start_response)
  File "/usr/lib/python2.6/site-packages/flask/app.py", line 1689, in wsgi_app
    response = self.make_response(self.handle_exception(e))
  File "/usr/lib/python2.6/site-packages/flask/app.py", line 1293, in handle_exception
    return handler(e)
TypeError: error() takes no arguments (1 given)
01/11/13 00:03:58 INFO: * Running on http://0.0.0.0:5692/
01/11/13 00:04:01 ERROR:Exception on /config [GET]
Traceback (most recent call last):
  File "/usr/lib/python2.6/site-packages/flask/app.py", line 1687, in wsgi_app
    response = self.full_dispatch_request()
  File "/usr/lib/python2.6/site-packages/flask/app.py", line 1360, in full_dispatch_request
    rv = self.handle_user_exception(e)
  File "/usr/lib/python2.6/site-packages/flask/app.py", line 1358, in full_dispatch_request
    rv = self.dispatch_request()
  File "/usr/lib/python2.6/site-packages/flask/app.py", line 1344, in dispatch_request
    return self.view_functions[rule.endpoint](**req.view_args)
  File "/tmp/ncpa/agent/listener/server.py", line 38, in config
    logging.exception(e)
NameError: global name 'e' is not defined
01/11/13 00:04:01 INFO:192.168.1.28 - - [11/Jan/2013 00:04:01] "GET /config HTTP/1.1" 500 -
01/11/13 00:04:01 ERROR:Error on request:
Traceback (most recent call last):
  File "/usr/lib/python2.6/site-packages/werkzeug/serving.py", line 159, in run_wsgi
    execute(app)
  File "/usr/lib/python2.6/site-packages/werkzeug/serving.py", line 146, in execute
    application_iter = app(environ, start_response)
  File "/usr/lib/python2.6/site-packages/flask/app.py", line 1701, in __call__
    return self.wsgi_app(environ, start_response)
  File "/usr/lib/python2.6/site-packages/flask/app.py", line 1689, in wsgi_app
    response = self.make_response(self.handle_exception(e))
  File "/usr/lib/python2.6/site-packages/flask/app.py", line 1293, in handle_exception
    return handler(e)
TypeError: error() takes no arguments (1 given)
01/11/13 00:04:22 ERROR:Exception on /config [GET]
Traceback (most recent call last):
  File "/usr/lib/python2.6/site-packages/flask/app.py", line 1687, in wsgi_app
    response = self.full_dispatch_request()
  File "/usr/lib/python2.6/site-packages/flask/app.py", line 1360, in full_dispatch_request
    rv = self.handle_user_exception(e)
  File "/usr/lib/python2.6/site-packages/flask/app.py", line 1358, in full_dispatch_request
    rv = self.dispatch_request()
  File "/usr/lib/python2.6/site-packages/flask/app.py", line 1344, in dispatch_request
    return self.view_functions[rule.endpoint](**req.view_args)
  File "/tmp/ncpa/agent/listener/server.py", line 38, in config
    logging.exception(e)
NameError: global name 'e' is not defined
01/11/13 00:04:22 INFO:192.168.1.28 - - [11/Jan/2013 00:04:22] "GET /config HTTP/1.1" 500 -
01/11/13 00:04:22 ERROR:Error on request:
Traceback (most recent call last):
  File "/usr/lib/python2.6/site-packages/werkzeug/serving.py", line 159, in run_wsgi
    execute(app)
  File "/usr/lib/python2.6/site-packages/werkzeug/serving.py", line 146, in execute
    application_iter = app(environ, start_response)
  File "/usr/lib/python2.6/site-packages/flask/app.py", line 1701, in __call__
    return self.wsgi_app(environ, start_response)
  File "/usr/lib/python2.6/site-packages/flask/app.py", line 1689, in wsgi_app
    response = self.make_response(self.handle_exception(e))
  File "/usr/lib/python2.6/site-packages/flask/app.py", line 1293, in handle_exception
    return handler(e)
TypeError: error() takes no arguments (1 given)
01/11/13 00:06:31 INFO: * Running on http://0.0.0.0:5692/
01/11/13 00:06:37 INFO:192.168.1.28 - - [11/Jan/2013 00:06:37] "GET /command/?command=enumerate_plugins HTTP/1.1" 200 -
01/11/13 00:08:01 INFO:192.168.1.28 - - [11/Jan/2013 00:08:01] "GET /main HTTP/1.1" 404 -
01/11/13 00:08:20 INFO:192.168.1.28 - - [11/Jan/2013 00:08:20] "GET / HTTP/1.1" 200 -
01/11/13 00:08:20 INFO:192.168.1.28 - - [11/Jan/2013 00:08:20] "GET /static/images/ui-bg_flat_75_ffffff_40x100.png HTTP/1.1" 404 -
01/11/13 00:08:20 INFO:192.168.1.28 - - [11/Jan/2013 00:08:20] "GET /static/images/ui-bg_highlight-soft_75_cccccc_1x100.png HTTP/1.1" 404 -
01/11/13 00:08:20 INFO:192.168.1.28 - - [11/Jan/2013 00:08:20] "GET /static/images/ui-bg_glass_75_e6e6e6_1x400.png HTTP/1.1" 404 -
01/11/13 00:08:20 INFO:192.168.1.28 - - [11/Jan/2013 00:08:20] "GET /static/images/ui-bg_glass_65_ffffff_1x400.png HTTP/1.1" 404 -
01/11/13 00:08:20 ERROR:Exception on /config [GET]
Traceback (most recent call last):
  File "/usr/lib/python2.6/site-packages/flask/app.py", line 1687, in wsgi_app
    response = self.full_dispatch_request()
  File "/usr/lib/python2.6/site-packages/flask/app.py", line 1360, in full_dispatch_request
    rv = self.handle_user_exception(e)
  File "/usr/lib/python2.6/site-packages/flask/app.py", line 1358, in full_dispatch_request
    rv = self.dispatch_request()
  File "/usr/lib/python2.6/site-packages/flask/app.py", line 1344, in dispatch_request
    return self.view_functions[rule.endpoint](**req.view_args)
  File "/tmp/ncpa/agent/listener/server.py", line 38, in config
    logging.exception(e)
NameError: global name 'e' is not defined
01/11/13 00:08:20 INFO:192.168.1.28 - - [11/Jan/2013 00:08:20] "GET /config HTTP/1.1" 500 -
01/11/13 00:08:20 ERROR:Error on request:
Traceback (most recent call last):
  File "/usr/lib/python2.6/site-packages/werkzeug/serving.py", line 159, in run_wsgi
    execute(app)
  File "/usr/lib/python2.6/site-packages/werkzeug/serving.py", line 146, in execute
    application_iter = app(environ, start_response)
  File "/usr/lib/python2.6/site-packages/flask/app.py", line 1701, in __call__
    return self.wsgi_app(environ, start_response)
  File "/usr/lib/python2.6/site-packages/flask/app.py", line 1689, in wsgi_app
    response = self.make_response(self.handle_exception(e))
  File "/usr/lib/python2.6/site-packages/flask/app.py", line 1293, in handle_exception
    return handler(e)
TypeError: error() takes no arguments (1 given)
01/11/13 00:08:27 INFO:192.168.1.28 - - [11/Jan/2013 00:08:27] "GET /static/images/ui-bg_glass_75_dadada_1x400.png HTTP/1.1" 404 -
01/11/13 00:08:39 INFO: * Running on http://0.0.0.0:5692/
01/11/13 00:08:43 INFO:192.168.1.28 - - [11/Jan/2013 00:08:43] "GET / HTTP/1.1" 200 -
01/11/13 00:08:44 INFO:192.168.1.28 - - [11/Jan/2013 00:08:44] "GET /static/images/ui-bg_flat_75_ffffff_40x100.png HTTP/1.1" 404 -
01/11/13 00:08:44 INFO:192.168.1.28 - - [11/Jan/2013 00:08:44] "GET /static/images/ui-bg_highlight-soft_75_cccccc_1x100.png HTTP/1.1" 404 -
01/11/13 00:08:44 INFO:192.168.1.28 - - [11/Jan/2013 00:08:44] "GET /static/images/ui-bg_glass_75_e6e6e6_1x400.png HTTP/1.1" 404 -
01/11/13 00:08:44 INFO:192.168.1.28 - - [11/Jan/2013 00:08:44] "GET /static/images/ui-bg_glass_65_ffffff_1x400.png HTTP/1.1" 404 -
01/11/13 00:08:44 ERROR:Exception on /config [GET]
Traceback (most recent call last):
  File "/usr/lib/python2.6/site-packages/flask/app.py", line 1687, in wsgi_app
    response = self.full_dispatch_request()
  File "/usr/lib/python2.6/site-packages/flask/app.py", line 1360, in full_dispatch_request
    rv = self.handle_user_exception(e)
  File "/usr/lib/python2.6/site-packages/flask/app.py", line 1358, in full_dispatch_request
    rv = self.dispatch_request()
  File "/usr/lib/python2.6/site-packages/flask/app.py", line 1344, in dispatch_request
    return self.view_functions[rule.endpoint](**req.view_args)
  File "/tmp/ncpa/agent/listener/server.py", line 37, in config
    logging.exception(e)
NameError: global name 'e' is not defined
01/11/13 00:08:44 INFO:192.168.1.28 - - [11/Jan/2013 00:08:44] "GET /config HTTP/1.1" 500 -
01/11/13 00:08:44 ERROR:Error on request:
Traceback (most recent call last):
  File "/usr/lib/python2.6/site-packages/werkzeug/serving.py", line 159, in run_wsgi
    execute(app)
  File "/usr/lib/python2.6/site-packages/werkzeug/serving.py", line 146, in execute
    application_iter = app(environ, start_response)
  File "/usr/lib/python2.6/site-packages/flask/app.py", line 1701, in __call__
    return self.wsgi_app(environ, start_response)
  File "/usr/lib/python2.6/site-packages/flask/app.py", line 1689, in wsgi_app
    response = self.make_response(self.handle_exception(e))
  File "/usr/lib/python2.6/site-packages/flask/app.py", line 1293, in handle_exception
    return handler(e)
TypeError: error() takes no arguments (1 given)
01/11/13 00:08:49 ERROR:Exception on /config [GET]
Traceback (most recent call last):
  File "/usr/lib/python2.6/site-packages/flask/app.py", line 1687, in wsgi_app
    response = self.full_dispatch_request()
  File "/usr/lib/python2.6/site-packages/flask/app.py", line 1360, in full_dispatch_request
    rv = self.handle_user_exception(e)
  File "/usr/lib/python2.6/site-packages/flask/app.py", line 1358, in full_dispatch_request
    rv = self.dispatch_request()
  File "/usr/lib/python2.6/site-packages/flask/app.py", line 1344, in dispatch_request
    return self.view_functions[rule.endpoint](**req.view_args)
  File "/tmp/ncpa/agent/listener/server.py", line 37, in config
    logging.exception(e)
NameError: global name 'e' is not defined
01/11/13 00:08:49 INFO:192.168.1.28 - - [11/Jan/2013 00:08:49] "GET /config HTTP/1.1" 500 -
01/11/13 00:08:49 ERROR:Error on request:
Traceback (most recent call last):
  File "/usr/lib/python2.6/site-packages/werkzeug/serving.py", line 159, in run_wsgi
    execute(app)
  File "/usr/lib/python2.6/site-packages/werkzeug/serving.py", line 146, in execute
    application_iter = app(environ, start_response)
  File "/usr/lib/python2.6/site-packages/flask/app.py", line 1701, in __call__
    return self.wsgi_app(environ, start_response)
  File "/usr/lib/python2.6/site-packages/flask/app.py", line 1689, in wsgi_app
    response = self.make_response(self.handle_exception(e))
  File "/usr/lib/python2.6/site-packages/flask/app.py", line 1293, in handle_exception
    return handler(e)
TypeError: error() takes no arguments (1 given)
01/11/13 00:09:32 INFO: * Running on http://0.0.0.0:5692/
01/11/13 00:09:36 ERROR:/tmp/ncpa/agent/etc/ncpa.cfg
01/11/13 00:09:36 ERROR:Exception on /config [GET]
Traceback (most recent call last):
  File "/usr/lib/python2.6/site-packages/flask/app.py", line 1687, in wsgi_app
    response = self.full_dispatch_request()
  File "/usr/lib/python2.6/site-packages/flask/app.py", line 1360, in full_dispatch_request
    rv = self.handle_user_exception(e)
  File "/usr/lib/python2.6/site-packages/flask/app.py", line 1358, in full_dispatch_request
    rv = self.dispatch_request()
  File "/usr/lib/python2.6/site-packages/flask/app.py", line 1344, in dispatch_request
    return self.view_functions[rule.endpoint](**req.view_args)
  File "/tmp/ncpa/agent/listener/server.py", line 37, in config
    logging.exception(e)
NameError: global name 'e' is not defined
01/11/13 00:09:36 INFO:192.168.1.28 - - [11/Jan/2013 00:09:36] "GET /config HTTP/1.1" 500 -
01/11/13 00:09:36 ERROR:Error on request:
Traceback (most recent call last):
  File "/usr/lib/python2.6/site-packages/werkzeug/serving.py", line 159, in run_wsgi
    execute(app)
  File "/usr/lib/python2.6/site-packages/werkzeug/serving.py", line 146, in execute
    application_iter = app(environ, start_response)
  File "/usr/lib/python2.6/site-packages/flask/app.py", line 1701, in __call__
    return self.wsgi_app(environ, start_response)
  File "/usr/lib/python2.6/site-packages/flask/app.py", line 1689, in wsgi_app
    response = self.make_response(self.handle_exception(e))
  File "/usr/lib/python2.6/site-packages/flask/app.py", line 1293, in handle_exception
    return handler(e)
TypeError: error() takes no arguments (1 given)
01/11/13 00:11:17 INFO:Starting server...
01/11/13 00:11:17 INFO: * Running on http://0.0.0.0:5692/
01/11/13 00:11:21 ERROR:/tmp/ncpa/agent/etc/ncpa.cfg
01/11/13 00:11:21 ERROR:Exception on /config [GET]
Traceback (most recent call last):
  File "/usr/lib/python2.6/site-packages/flask/app.py", line 1687, in wsgi_app
    response = self.full_dispatch_request()
  File "/usr/lib/python2.6/site-packages/flask/app.py", line 1360, in full_dispatch_request
    rv = self.handle_user_exception(e)
  File "/usr/lib/python2.6/site-packages/flask/app.py", line 1358, in full_dispatch_request
    rv = self.dispatch_request()
  File "/usr/lib/python2.6/site-packages/flask/app.py", line 1344, in dispatch_request
    return self.view_functions[rule.endpoint](**req.view_args)
  File "/tmp/ncpa/agent/listener/server.py", line 37, in config
    logging.exception(e)
NameError: global name 'e' is not defined
01/11/13 00:11:21 INFO:192.168.1.28 - - [11/Jan/2013 00:11:21] "GET /config HTTP/1.1" 500 -
01/11/13 00:11:21 ERROR:Error on request:
Traceback (most recent call last):
  File "/usr/lib/python2.6/site-packages/werkzeug/serving.py", line 159, in run_wsgi
    execute(app)
  File "/usr/lib/python2.6/site-packages/werkzeug/serving.py", line 146, in execute
    application_iter = app(environ, start_response)
  File "/usr/lib/python2.6/site-packages/flask/app.py", line 1701, in __call__
    return self.wsgi_app(environ, start_response)
  File "/usr/lib/python2.6/site-packages/flask/app.py", line 1689, in wsgi_app
    response = self.make_response(self.handle_exception(e))
  File "/usr/lib/python2.6/site-packages/flask/app.py", line 1293, in handle_exception
    return handler(e)
TypeError: error() takes no arguments (1 given)
01/11/13 00:12:36 ERROR:/tmp/ncpa/agent/etc/ncpa.cfg
01/11/13 00:12:36 ERROR:Exception on /config [GET]
Traceback (most recent call last):
  File "/usr/lib/python2.6/site-packages/flask/app.py", line 1687, in wsgi_app
    response = self.full_dispatch_request()
  File "/usr/lib/python2.6/site-packages/flask/app.py", line 1360, in full_dispatch_request
    rv = self.handle_user_exception(e)
  File "/usr/lib/python2.6/site-packages/flask/app.py", line 1358, in full_dispatch_request
    rv = self.dispatch_request()
  File "/usr/lib/python2.6/site-packages/flask/app.py", line 1344, in dispatch_request
    return self.view_functions[rule.endpoint](**req.view_args)
  File "/tmp/ncpa/agent/listener/server.py", line 37, in config
    logging.exception(e)
NameError: global name 'e' is not defined
01/11/13 00:12:36 INFO:192.168.1.28 - - [11/Jan/2013 00:12:36] "GET /config HTTP/1.1" 500 -
01/11/13 00:12:36 ERROR:Error on request:
Traceback (most recent call last):
  File "/usr/lib/python2.6/site-packages/werkzeug/serving.py", line 159, in run_wsgi
    execute(app)
  File "/usr/lib/python2.6/site-packages/werkzeug/serving.py", line 146, in execute
    application_iter = app(environ, start_response)
  File "/usr/lib/python2.6/site-packages/flask/app.py", line 1701, in __call__
    return self.wsgi_app(environ, start_response)
  File "/usr/lib/python2.6/site-packages/flask/app.py", line 1689, in wsgi_app
    response = self.make_response(self.handle_exception(e))
  File "/usr/lib/python2.6/site-packages/flask/app.py", line 1293, in handle_exception
    return handler(e)
TypeError: error() takes no arguments (1 given)
01/11/13 00:13:11 ERROR:/tmp/ncpa/agent/etc/ncpa.cfg
01/11/13 00:13:11 ERROR:Exception on /config [GET]
Traceback (most recent call last):
  File "/usr/lib/python2.6/site-packages/flask/app.py", line 1687, in wsgi_app
    response = self.full_dispatch_request()
  File "/usr/lib/python2.6/site-packages/flask/app.py", line 1360, in full_dispatch_request
    rv = self.handle_user_exception(e)
  File "/usr/lib/python2.6/site-packages/flask/app.py", line 1358, in full_dispatch_request
    rv = self.dispatch_request()
  File "/usr/lib/python2.6/site-packages/flask/app.py", line 1344, in dispatch_request
    return self.view_functions[rule.endpoint](**req.view_args)
  File "/tmp/ncpa/agent/listener/server.py", line 37, in config
    logging.exception(e)
NameError: global name 'e' is not defined
01/11/13 00:13:11 INFO:192.168.1.28 - - [11/Jan/2013 00:13:11] "GET /config HTTP/1.1" 500 -
01/11/13 00:13:11 ERROR:Error on request:
Traceback (most recent call last):
  File "/usr/lib/python2.6/site-packages/werkzeug/serving.py", line 159, in run_wsgi
    execute(app)
  File "/usr/lib/python2.6/site-packages/werkzeug/serving.py", line 146, in execute
    application_iter = app(environ, start_response)
  File "/usr/lib/python2.6/site-packages/flask/app.py", line 1701, in __call__
    return self.wsgi_app(environ, start_response)
  File "/usr/lib/python2.6/site-packages/flask/app.py", line 1689, in wsgi_app
    response = self.make_response(self.handle_exception(e))
  File "/usr/lib/python2.6/site-packages/flask/app.py", line 1293, in handle_exception
    return handler(e)
TypeError: error() takes no arguments (1 given)
01/11/13 00:13:45 ERROR:/tmp/ncpa/agent/etc/ncpa.cfg
01/11/13 00:13:45 ERROR:Exception on /config [GET]
Traceback (most recent call last):
  File "/usr/lib/python2.6/site-packages/flask/app.py", line 1687, in wsgi_app
    response = self.full_dispatch_request()
  File "/usr/lib/python2.6/site-packages/flask/app.py", line 1360, in full_dispatch_request
    rv = self.handle_user_exception(e)
  File "/usr/lib/python2.6/site-packages/flask/app.py", line 1358, in full_dispatch_request
    rv = self.dispatch_request()
  File "/usr/lib/python2.6/site-packages/flask/app.py", line 1344, in dispatch_request
    return self.view_functions[rule.endpoint](**req.view_args)
  File "/tmp/ncpa/agent/listener/server.py", line 37, in config
    params = urllib.urlencode({'msg' : str(e)})
NameError: global name 'e' is not defined
01/11/13 00:13:45 INFO:192.168.1.28 - - [11/Jan/2013 00:13:45] "GET /config HTTP/1.1" 500 -
01/11/13 00:13:45 ERROR:Error on request:
Traceback (most recent call last):
  File "/usr/lib/python2.6/site-packages/werkzeug/serving.py", line 159, in run_wsgi
    execute(app)
  File "/usr/lib/python2.6/site-packages/werkzeug/serving.py", line 146, in execute
    application_iter = app(environ, start_response)
  File "/usr/lib/python2.6/site-packages/flask/app.py", line 1701, in __call__
    return self.wsgi_app(environ, start_response)
  File "/usr/lib/python2.6/site-packages/flask/app.py", line 1689, in wsgi_app
    response = self.make_response(self.handle_exception(e))
  File "/usr/lib/python2.6/site-packages/flask/app.py", line 1293, in handle_exception
    return handler(e)
TypeError: error() takes no arguments (1 given)
01/11/13 00:15:52 INFO:192.168.1.28 - - [11/Jan/2013 00:15:52] "GET /command?command=enumerate_plugins HTTP/1.1" 301 -
01/11/13 00:15:52 INFO:192.168.1.28 - - [11/Jan/2013 00:15:52] "GET /command/?command=enumerate_plugins HTTP/1.1" 200 -
01/11/13 00:16:07 INFO: * Running on http://0.0.0.0:5692/
01/11/13 00:16:09 ERROR:local variable 'externals' referenced before assignment
Traceback (most recent call last):
  File "/tmp/ncpa/agent/listener/commands.py", line 8, in enumerate_plugins
    externals += [x for x in os.listdir('plugins') if os.path.isfile('plugins/%s' % x)]
UnboundLocalError: local variable 'externals' referenced before assignment
01/11/13 00:16:09 INFO:192.168.1.28 - - [11/Jan/2013 00:16:09] "GET /command/?command=enumerate_plugins HTTP/1.1" 200 -
01/11/13 00:16:31 INFO: * Running on http://0.0.0.0:5692/
01/11/13 00:16:32 INFO:192.168.1.28 - - [11/Jan/2013 00:16:32] "GET /command/?command=enumerate_plugins HTTP/1.1" 200 -
01/11/13 00:27:14 INFO: * Running on http://0.0.0.0:5692/
01/11/13 00:27:23 INFO:192.168.1.28 - - [11/Jan/2013 00:27:23] "GET /command/?command=enumerate_plugins HTTP/1.1" 200 -
01/11/13 00:27:29 ERROR:/tmp/ncpa/agent/etc/ncpa.cfg
01/11/13 00:27:29 ERROR:Exception on /config [GET]
Traceback (most recent call last):
  File "/usr/lib/python2.6/site-packages/flask/app.py", line 1687, in wsgi_app
    response = self.full_dispatch_request()
  File "/usr/lib/python2.6/site-packages/flask/app.py", line 1360, in full_dispatch_request
    rv = self.handle_user_exception(e)
  File "/usr/lib/python2.6/site-packages/flask/app.py", line 1358, in full_dispatch_request
    rv = self.dispatch_request()
  File "/usr/lib/python2.6/site-packages/flask/app.py", line 1344, in dispatch_request
    return self.view_functions[rule.endpoint](**req.view_args)
  File "/tmp/ncpa/agent/listener/server.py", line 41, in config
    logging.exception(e)
NameError: global name 'e' is not defined
01/11/13 00:27:29 INFO:192.168.1.28 - - [11/Jan/2013 00:27:29] "GET /config HTTP/1.1" 500 -
01/11/13 00:27:53 INFO: * Running on http://0.0.0.0:5692/
01/11/13 00:27:56 ERROR:Exception on /config [GET]
Traceback (most recent call last):
  File "/usr/lib/python2.6/site-packages/flask/app.py", line 1687, in wsgi_app
    response = self.full_dispatch_request()
  File "/usr/lib/python2.6/site-packages/flask/app.py", line 1360, in full_dispatch_request
    rv = self.handle_user_exception(e)
  File "/usr/lib/python2.6/site-packages/flask/app.py", line 1358, in full_dispatch_request
    rv = self.dispatch_request()
  File "/usr/lib/python2.6/site-packages/flask/app.py", line 1344, in dispatch_request
    return self.view_functions[rule.endpoint](**req.view_args)
  File "/tmp/ncpa/agent/listener/server.py", line 38, in config
    logging.exception(e)
NameError: global name 'e' is not defined
01/11/13 00:27:56 INFO:192.168.1.28 - - [11/Jan/2013 00:27:56] "GET /config HTTP/1.1" 500 -
01/11/13 00:28:22 INFO: * Running on http://0.0.0.0:5692/
01/11/13 00:28:25 ERROR:Exception on /config [GET]
Traceback (most recent call last):
  File "/usr/lib/python2.6/site-packages/flask/app.py", line 1687, in wsgi_app
    response = self.full_dispatch_request()
  File "/usr/lib/python2.6/site-packages/flask/app.py", line 1360, in full_dispatch_request
    rv = self.handle_user_exception(e)
  File "/usr/lib/python2.6/site-packages/flask/app.py", line 1358, in full_dispatch_request
    rv = self.dispatch_request()
  File "/usr/lib/python2.6/site-packages/flask/app.py", line 1344, in dispatch_request
    return self.view_functions[rule.endpoint](**req.view_args)
  File "/tmp/ncpa/agent/listener/server.py", line 39, in config
    logging.exception(e)
NameError: global name 'e' is not defined
01/11/13 00:28:25 INFO:192.168.1.28 - - [11/Jan/2013 00:28:25] "GET /config HTTP/1.1" 500 -
01/11/13 00:31:44 ERROR:'Config' object has no attribute 'set'
Traceback (most recent call last):
  File "/tmp/ncpa/agent/daemons/posix.py", line 177, in start
    listener.server.listener.config.set('iconfig', self.config)
AttributeError: 'Config' object has no attribute 'set'
01/11/13 00:32:28 INFO: * Running on http://0.0.0.0:5692/
01/11/13 00:32:34 ERROR:Exception on /config [GET]
Traceback (most recent call last):
  File "/usr/lib/python2.6/site-packages/flask/app.py", line 1687, in wsgi_app
    response = self.full_dispatch_request()
  File "/usr/lib/python2.6/site-packages/flask/app.py", line 1360, in full_dispatch_request
    rv = self.handle_user_exception(e)
  File "/usr/lib/python2.6/site-packages/flask/app.py", line 1358, in full_dispatch_request
    rv = self.dispatch_request()
  File "/usr/lib/python2.6/site-packages/flask/app.py", line 1344, in dispatch_request
    return self.view_functions[rule.endpoint](**req.view_args)
  File "/tmp/ncpa/agent/listener/server.py", line 39, in config
    logging.exception(e)
NameError: global name 'e' is not defined
01/11/13 00:32:34 INFO:192.168.1.28 - - [11/Jan/2013 00:32:34] "GET /config HTTP/1.1" 500 -
01/11/13 00:32:55 INFO: * Running on http://0.0.0.0:5692/
01/11/13 00:32:59 ERROR:render_template() takes exactly 1 argument (2 given)
Traceback (most recent call last):
  File "/tmp/ncpa/agent/listener/server.py", line 37, in config
    return render_template('config.html', {'config' : {'hi' : 'there'}})
TypeError: render_template() takes exactly 1 argument (2 given)
01/11/13 00:32:59 ERROR:Exception on /config [GET]
Traceback (most recent call last):
  File "/usr/lib/python2.6/site-packages/flask/app.py", line 1687, in wsgi_app
    response = self.full_dispatch_request()
  File "/usr/lib/python2.6/site-packages/flask/app.py", line 1360, in full_dispatch_request
    rv = self.handle_user_exception(e)
  File "/usr/lib/python2.6/site-packages/flask/app.py", line 1358, in full_dispatch_request
    rv = self.dispatch_request()
  File "/usr/lib/python2.6/site-packages/flask/app.py", line 1344, in dispatch_request
    return self.view_functions[rule.endpoint](**req.view_args)
  File "/tmp/ncpa/agent/listener/server.py", line 41, in config
    redirect(url_for('/error?%s' % params))
  File "/usr/lib/python2.6/site-packages/flask/helpers.py", line 361, in url_for
    return appctx.app.handle_url_build_error(error, endpoint, values)
  File "/usr/lib/python2.6/site-packages/flask/helpers.py", line 354, in url_for
    force_external=external)
  File "/usr/lib/python2.6/site-packages/werkzeug/routing.py", line 1607, in build
    raise BuildError(endpoint, values, method)
BuildError: ('/error?msg=render_template%28%29+takes+exactly+1+argument+%282+given%29', {}, None)
01/11/13 00:32:59 INFO:192.168.1.28 - - [11/Jan/2013 00:32:59] "GET /config HTTP/1.1" 500 -
01/11/13 00:33:44 INFO: * Running on http://0.0.0.0:5692/
01/11/13 00:33:51 INFO:192.168.1.28 - - [11/Jan/2013 00:33:51] "GET /config HTTP/1.1" 301 -
01/11/13 00:33:51 ERROR:render_template() takes exactly 1 argument (2 given)
Traceback (most recent call last):
  File "/tmp/ncpa/agent/listener/server.py", line 37, in config
    return render_template('config.html', {'config' : {'hi' : 'there'}})
TypeError: render_template() takes exactly 1 argument (2 given)
01/11/13 00:33:51 ERROR:Exception on /config/ [GET]
Traceback (most recent call last):
  File "/usr/lib/python2.6/site-packages/flask/app.py", line 1687, in wsgi_app
    response = self.full_dispatch_request()
  File "/usr/lib/python2.6/site-packages/flask/app.py", line 1360, in full_dispatch_request
    rv = self.handle_user_exception(e)
  File "/usr/lib/python2.6/site-packages/flask/app.py", line 1358, in full_dispatch_request
    rv = self.dispatch_request()
  File "/usr/lib/python2.6/site-packages/flask/app.py", line 1344, in dispatch_request
    return self.view_functions[rule.endpoint](**req.view_args)
  File "/tmp/ncpa/agent/listener/server.py", line 41, in config
    redirect(url_for('/error?%s' % params))
  File "/usr/lib/python2.6/site-packages/flask/helpers.py", line 361, in url_for
    return appctx.app.handle_url_build_error(error, endpoint, values)
  File "/usr/lib/python2.6/site-packages/flask/helpers.py", line 354, in url_for
    force_external=external)
  File "/usr/lib/python2.6/site-packages/werkzeug/routing.py", line 1607, in build
    raise BuildError(endpoint, values, method)
BuildError: ('/error?msg=render_template%28%29+takes+exactly+1+argument+%282+given%29', {}, None)
01/11/13 00:33:51 INFO:192.168.1.28 - - [11/Jan/2013 00:33:51] "GET /config/ HTTP/1.1" 500 -
01/11/13 00:34:36 INFO: * Running on http://0.0.0.0:5692/
01/11/13 00:34:39 ERROR:render_template() takes exactly 1 argument (2 given)
Traceback (most recent call last):
  File "/tmp/ncpa/agent/listener/server.py", line 37, in config
    return render_template('config.html', {'config' : {'hi' : 'there'}})
TypeError: render_template() takes exactly 1 argument (2 given)
01/11/13 00:34:39 ERROR:Exception on /config/ [GET]
Traceback (most recent call last):
  File "/usr/lib/python2.6/site-packages/flask/app.py", line 1687, in wsgi_app
    response = self.full_dispatch_request()
  File "/usr/lib/python2.6/site-packages/flask/app.py", line 1360, in full_dispatch_request
    rv = self.handle_user_exception(e)
  File "/usr/lib/python2.6/site-packages/flask/app.py", line 1358, in full_dispatch_request
    rv = self.dispatch_request()
  File "/usr/lib/python2.6/site-packages/flask/app.py", line 1344, in dispatch_request
    return self.view_functions[rule.endpoint](**req.view_args)
  File "/tmp/ncpa/agent/listener/server.py", line 41, in config
    redirect(url_for('/error?%s' % params))
  File "/usr/lib/python2.6/site-packages/flask/helpers.py", line 361, in url_for
    return appctx.app.handle_url_build_error(error, endpoint, values)
  File "/usr/lib/python2.6/site-packages/flask/helpers.py", line 354, in url_for
    force_external=external)
  File "/usr/lib/python2.6/site-packages/werkzeug/routing.py", line 1607, in build
    raise BuildError(endpoint, values, method)
BuildError: ('/error?msg=render_template%28%29+takes+exactly+1+argument+%282+given%29', {}, None)
01/11/13 00:34:39 INFO:192.168.1.28 - - [11/Jan/2013 00:34:39] "GET /config/ HTTP/1.1" 500 -
01/11/13 00:35:03 ERROR:render_template() takes exactly 1 argument (2 given)
Traceback (most recent call last):
  File "/tmp/ncpa/agent/listener/server.py", line 37, in config
    return render_template('config.html', {'config' : {'hi' : 'there'}})
TypeError: render_template() takes exactly 1 argument (2 given)
01/11/13 00:35:03 ERROR:Exception on /config/ [GET]
Traceback (most recent call last):
  File "/usr/lib/python2.6/site-packages/flask/app.py", line 1687, in wsgi_app
    response = self.full_dispatch_request()
  File "/usr/lib/python2.6/site-packages/flask/app.py", line 1360, in full_dispatch_request
    rv = self.handle_user_exception(e)
  File "/usr/lib/python2.6/site-packages/flask/app.py", line 1358, in full_dispatch_request
    rv = self.dispatch_request()
  File "/usr/lib/python2.6/site-packages/flask/app.py", line 1344, in dispatch_request
    return self.view_functions[rule.endpoint](**req.view_args)
  File "/tmp/ncpa/agent/listener/server.py", line 41, in config
    redirect(url_for('/error?%s' % params))
  File "/usr/lib/python2.6/site-packages/flask/helpers.py", line 361, in url_for
    return appctx.app.handle_url_build_error(error, endpoint, values)
  File "/usr/lib/python2.6/site-packages/flask/helpers.py", line 354, in url_for
    force_external=external)
  File "/usr/lib/python2.6/site-packages/werkzeug/routing.py", line 1607, in build
    raise BuildError(endpoint, values, method)
BuildError: ('/error?msg=render_template%28%29+takes+exactly+1+argument+%282+given%29', {}, None)
01/11/13 00:35:03 INFO:192.168.1.28 - - [11/Jan/2013 00:35:03] "GET /config/ HTTP/1.1" 500 -
01/11/13 00:35:12 INFO: * Running on http://0.0.0.0:5692/
01/11/13 00:35:15 ERROR:render_template() takes exactly 1 argument (2 given)
Traceback (most recent call last):
  File "/tmp/ncpa/agent/listener/server.py", line 37, in config
    return render_template('config.html', {'config' : {'hi' : 'there'}})
TypeError: render_template() takes exactly 1 argument (2 given)
01/11/13 00:35:15 ERROR:Exception on /config/ [GET]
Traceback (most recent call last):
  File "/usr/lib/python2.6/site-packages/flask/app.py", line 1687, in wsgi_app
    response = self.full_dispatch_request()
  File "/usr/lib/python2.6/site-packages/flask/app.py", line 1360, in full_dispatch_request
    rv = self.handle_user_exception(e)
  File "/usr/lib/python2.6/site-packages/flask/app.py", line 1358, in full_dispatch_request
    rv = self.dispatch_request()
  File "/usr/lib/python2.6/site-packages/flask/app.py", line 1344, in dispatch_request
    return self.view_functions[rule.endpoint](**req.view_args)
  File "/tmp/ncpa/agent/listener/server.py", line 41, in config
    redirect(url_for('/error?%s' % params))
  File "/usr/lib/python2.6/site-packages/flask/helpers.py", line 361, in url_for
    return appctx.app.handle_url_build_error(error, endpoint, values)
  File "/usr/lib/python2.6/site-packages/flask/helpers.py", line 354, in url_for
    force_external=external)
  File "/usr/lib/python2.6/site-packages/werkzeug/routing.py", line 1607, in build
    raise BuildError(endpoint, values, method)
BuildError: ('/error?msg=render_template%28%29+takes+exactly+1+argument+%282+given%29', {}, None)
01/11/13 00:35:15 INFO:192.168.1.28 - - [11/Jan/2013 00:35:15] "GET /config/ HTTP/1.1" 500 -
01/11/13 00:35:22 ERROR:render_template() takes exactly 1 argument (2 given)
Traceback (most recent call last):
  File "/tmp/ncpa/agent/listener/server.py", line 37, in config
    return render_template('config.html', {'config' : {'hi' : 'there'}})
TypeError: render_template() takes exactly 1 argument (2 given)
01/11/13 00:35:22 ERROR:Exception on /config/ [GET]
Traceback (most recent call last):
  File "/usr/lib/python2.6/site-packages/flask/app.py", line 1687, in wsgi_app
    response = self.full_dispatch_request()
  File "/usr/lib/python2.6/site-packages/flask/app.py", line 1360, in full_dispatch_request
    rv = self.handle_user_exception(e)
  File "/usr/lib/python2.6/site-packages/flask/app.py", line 1358, in full_dispatch_request
    rv = self.dispatch_request()
  File "/usr/lib/python2.6/site-packages/flask/app.py", line 1344, in dispatch_request
    return self.view_functions[rule.endpoint](**req.view_args)
  File "/tmp/ncpa/agent/listener/server.py", line 41, in config
    redirect(url_for('/error?%s' % params))
  File "/usr/lib/python2.6/site-packages/flask/helpers.py", line 361, in url_for
    return appctx.app.handle_url_build_error(error, endpoint, values)
  File "/usr/lib/python2.6/site-packages/flask/helpers.py", line 354, in url_for
    force_external=external)
  File "/usr/lib/python2.6/site-packages/werkzeug/routing.py", line 1607, in build
    raise BuildError(endpoint, values, method)
BuildError: ('/error?msg=render_template%28%29+takes+exactly+1+argument+%282+given%29', {}, None)
01/11/13 00:35:22 INFO:192.168.1.28 - - [11/Jan/2013 00:35:22] "GET /config/ HTTP/1.1" 500 -
01/11/13 00:35:56 INFO: * Running on http://0.0.0.0:5692/
01/11/13 00:35:58 ERROR:render_template() takes exactly 1 argument (2 given)
Traceback (most recent call last):
  File "/tmp/ncpa/agent/listener/server.py", line 37, in config
    return render_template('config.html', {'config' : {'hi' : 'there'}})
TypeError: render_template() takes exactly 1 argument (2 given)
01/11/13 00:35:58 ERROR:Exception on /config/ [GET]
Traceback (most recent call last):
  File "/usr/lib/python2.6/site-packages/flask/app.py", line 1687, in wsgi_app
    response = self.full_dispatch_request()
  File "/usr/lib/python2.6/site-packages/flask/app.py", line 1360, in full_dispatch_request
    rv = self.handle_user_exception(e)
  File "/usr/lib/python2.6/site-packages/flask/app.py", line 1358, in full_dispatch_request
    rv = self.dispatch_request()
  File "/usr/lib/python2.6/site-packages/flask/app.py", line 1344, in dispatch_request
    return self.view_functions[rule.endpoint](**req.view_args)
  File "/tmp/ncpa/agent/listener/server.py", line 41, in config
    redirect(url_for('/error/?%s' % params))
  File "/usr/lib/python2.6/site-packages/flask/helpers.py", line 361, in url_for
    return appctx.app.handle_url_build_error(error, endpoint, values)
  File "/usr/lib/python2.6/site-packages/flask/helpers.py", line 354, in url_for
    force_external=external)
  File "/usr/lib/python2.6/site-packages/werkzeug/routing.py", line 1607, in build
    raise BuildError(endpoint, values, method)
BuildError: ('/error/?msg=render_template%28%29+takes+exactly+1+argument+%282+given%29', {}, None)
01/11/13 00:35:58 INFO:192.168.1.28 - - [11/Jan/2013 00:35:58] "GET /config/ HTTP/1.1" 500 -
01/11/13 00:36:54 INFO: * Running on http://0.0.0.0:5692/
01/11/13 00:36:57 ERROR:render_template() takes exactly 1 argument (2 given)
Traceback (most recent call last):
  File "/tmp/ncpa/agent/listener/server.py", line 37, in config
    return render_template('config.html', {'config' : {'hi' : 'there'}})
TypeError: render_template() takes exactly 1 argument (2 given)
01/11/13 00:36:57 ERROR:Exception on /config/ [GET]
Traceback (most recent call last):
  File "/usr/lib/python2.6/site-packages/flask/app.py", line 1687, in wsgi_app
    response = self.full_dispatch_request()
  File "/usr/lib/python2.6/site-packages/flask/app.py", line 1360, in full_dispatch_request
    rv = self.handle_user_exception(e)
  File "/usr/lib/python2.6/site-packages/flask/app.py", line 1358, in full_dispatch_request
    rv = self.dispatch_request()
  File "/usr/lib/python2.6/site-packages/flask/app.py", line 1344, in dispatch_request
    return self.view_functions[rule.endpoint](**req.view_args)
  File "/tmp/ncpa/agent/listener/server.py", line 41, in config
    redirect(url_for('/error/?%s' % params))
  File "/usr/lib/python2.6/site-packages/flask/helpers.py", line 361, in url_for
    return appctx.app.handle_url_build_error(error, endpoint, values)
  File "/usr/lib/python2.6/site-packages/flask/helpers.py", line 354, in url_for
    force_external=external)
  File "/usr/lib/python2.6/site-packages/werkzeug/routing.py", line 1607, in build
    raise BuildError(endpoint, values, method)
BuildError: ('/error/?msg=render_template%28%29+takes+exactly+1+argument+%282+given%29', {}, None)
01/11/13 00:36:57 INFO:192.168.1.28 - - [11/Jan/2013 00:36:57] "GET /config/ HTTP/1.1" 500 -
01/11/13 00:38:56 INFO: * Running on http://0.0.0.0:5692/
01/11/13 00:39:19 ERROR:'Flask' object has no attribute 'pconfig'
Traceback (most recent call last):
  File "/tmp/ncpa/agent/listener/server.py", line 36, in config
    return render_template('config.html', **{'config' : listener.pconfig.__dict__['_sections']})
AttributeError: 'Flask' object has no attribute 'pconfig'
01/11/13 00:39:19 ERROR:Exception on /config/ [GET]
Traceback (most recent call last):
  File "/usr/lib/python2.6/site-packages/flask/app.py", line 1687, in wsgi_app
    response = self.full_dispatch_request()
  File "/usr/lib/python2.6/site-packages/flask/app.py", line 1360, in full_dispatch_request
    rv = self.handle_user_exception(e)
  File "/usr/lib/python2.6/site-packages/flask/app.py", line 1358, in full_dispatch_request
    rv = self.dispatch_request()
  File "/usr/lib/python2.6/site-packages/flask/app.py", line 1344, in dispatch_request
    return self.view_functions[rule.endpoint](**req.view_args)
  File "/tmp/ncpa/agent/listener/server.py", line 41, in config
    redirect(url_for('listener', '/error/?%s' % params))
TypeError: url_for() takes exactly 1 argument (2 given)
01/11/13 00:39:19 INFO:192.168.1.28 - - [11/Jan/2013 00:39:19] "GET /config/ HTTP/1.1" 500 -
01/11/13 00:39:49 INFO: * Running on http://0.0.0.0:5692/
01/11/13 00:39:51 ERROR:'Flask' object has no attribute 'pconfig'
Traceback (most recent call last):
  File "/tmp/ncpa/agent/listener/server.py", line 36, in config
    return render_template('config.html', **{'config' : listener.pconfig.__dict__['_sections']})
AttributeError: 'Flask' object has no attribute 'pconfig'
01/11/13 00:39:51 ERROR:Exception on /config/ [GET]
Traceback (most recent call last):
  File "/usr/lib/python2.6/site-packages/flask/app.py", line 1687, in wsgi_app
    response = self.full_dispatch_request()
  File "/usr/lib/python2.6/site-packages/flask/app.py", line 1360, in full_dispatch_request
    rv = self.handle_user_exception(e)
  File "/usr/lib/python2.6/site-packages/flask/app.py", line 1358, in full_dispatch_request
    rv = self.dispatch_request()
  File "/usr/lib/python2.6/site-packages/flask/app.py", line 1344, in dispatch_request
    return self.view_functions[rule.endpoint](**req.view_args)
  File "/tmp/ncpa/agent/listener/server.py", line 41, in config
    redirect(url_for('/error/?%s' % params))
  File "/usr/lib/python2.6/site-packages/flask/helpers.py", line 361, in url_for
    return appctx.app.handle_url_build_error(error, endpoint, values)
  File "/usr/lib/python2.6/site-packages/flask/helpers.py", line 354, in url_for
    force_external=external)
  File "/usr/lib/python2.6/site-packages/werkzeug/routing.py", line 1607, in build
    raise BuildError(endpoint, values, method)
BuildError: ('/error/?msg=%27Flask%27+object+has+no+attribute+%27pconfig%27', {}, None)
01/11/13 00:39:51 INFO:192.168.1.28 - - [11/Jan/2013 00:39:51] "GET /config/ HTTP/1.1" 500 -
01/11/13 00:40:39 INFO: * Running on http://0.0.0.0:5692/
01/11/13 00:40:42 ERROR:'iconfig'
Traceback (most recent call last):
  File "/tmp/ncpa/agent/listener/server.py", line 36, in config
    return render_template('config.html', **{'config' : listener.config.__dict__['iconfig']['_sections']})
KeyError: 'iconfig'
01/11/13 00:40:42 ERROR:Exception on /config/ [GET]
Traceback (most recent call last):
  File "/usr/lib/python2.6/site-packages/flask/app.py", line 1687, in wsgi_app
    response = self.full_dispatch_request()
  File "/usr/lib/python2.6/site-packages/flask/app.py", line 1360, in full_dispatch_request
    rv = self.handle_user_exception(e)
  File "/usr/lib/python2.6/site-packages/flask/app.py", line 1358, in full_dispatch_request
    rv = self.dispatch_request()
  File "/usr/lib/python2.6/site-packages/flask/app.py", line 1344, in dispatch_request
    return self.view_functions[rule.endpoint](**req.view_args)
  File "/tmp/ncpa/agent/listener/server.py", line 41, in config
    redirect(url_for('/error/?%s' % params))
  File "/usr/lib/python2.6/site-packages/flask/helpers.py", line 361, in url_for
    return appctx.app.handle_url_build_error(error, endpoint, values)
  File "/usr/lib/python2.6/site-packages/flask/helpers.py", line 354, in url_for
    force_external=external)
  File "/usr/lib/python2.6/site-packages/werkzeug/routing.py", line 1607, in build
    raise BuildError(endpoint, values, method)
BuildError: ('/error/?msg=%27iconfig%27', {}, None)
01/11/13 00:40:42 INFO:192.168.1.28 - - [11/Jan/2013 00:40:42] "GET /config/ HTTP/1.1" 500 -
01/11/13 00:41:31 INFO: * Running on http://0.0.0.0:5692/
01/11/13 00:41:37 ERROR:'iconfig'
Traceback (most recent call last):
  File "/tmp/ncpa/agent/listener/server.py", line 36, in config
    return render_template('config.html', **{'config' : listener.config.__dict__['iconfig']})
KeyError: 'iconfig'
01/11/13 00:41:37 ERROR:Exception on /config/ [GET]
Traceback (most recent call last):
  File "/usr/lib/python2.6/site-packages/flask/app.py", line 1687, in wsgi_app
    response = self.full_dispatch_request()
  File "/usr/lib/python2.6/site-packages/flask/app.py", line 1360, in full_dispatch_request
    rv = self.handle_user_exception(e)
  File "/usr/lib/python2.6/site-packages/flask/app.py", line 1358, in full_dispatch_request
    rv = self.dispatch_request()
  File "/usr/lib/python2.6/site-packages/flask/app.py", line 1344, in dispatch_request
    return self.view_functions[rule.endpoint](**req.view_args)
  File "/tmp/ncpa/agent/listener/server.py", line 41, in config
    redirect(url_for('/error/?%s' % params))
  File "/usr/lib/python2.6/site-packages/flask/helpers.py", line 361, in url_for
    return appctx.app.handle_url_build_error(error, endpoint, values)
  File "/usr/lib/python2.6/site-packages/flask/helpers.py", line 354, in url_for
    force_external=external)
  File "/usr/lib/python2.6/site-packages/werkzeug/routing.py", line 1607, in build
    raise BuildError(endpoint, values, method)
BuildError: ('/error/?msg=%27iconfig%27', {}, None)
01/11/13 00:41:37 INFO:192.168.1.28 - - [11/Jan/2013 00:41:37] "GET /config/ HTTP/1.1" 500 -
01/11/13 00:42:29 INFO: * Running on http://0.0.0.0:5692/
01/11/13 00:42:31 ERROR:items() takes at least 2 arguments (1 given)
Traceback (most recent call last):
  File "/tmp/ncpa/agent/listener/server.py", line 36, in config
    return render_template('config.html', **{'config' : listener.config['iconfig']})
  File "/usr/lib/python2.6/site-packages/flask/templating.py", line 125, in render_template
    context, ctx.app)
  File "/usr/lib/python2.6/site-packages/flask/templating.py", line 107, in _render
    rv = template.render(context)
  File "/usr/lib/python2.6/site-packages/jinja2/environment.py", line 894, in render
    return self.environment.handle_exception(exc_info, True)
  File "/tmp/ncpa/agent/listener/templates/config.html", line 6, in top-level template code
    {% for section, value in config.items() %}
TypeError: items() takes at least 2 arguments (1 given)
01/11/13 00:42:31 ERROR:Exception on /config/ [GET]
Traceback (most recent call last):
  File "/usr/lib/python2.6/site-packages/flask/app.py", line 1687, in wsgi_app
    response = self.full_dispatch_request()
  File "/usr/lib/python2.6/site-packages/flask/app.py", line 1360, in full_dispatch_request
    rv = self.handle_user_exception(e)
  File "/usr/lib/python2.6/site-packages/flask/app.py", line 1358, in full_dispatch_request
    rv = self.dispatch_request()
  File "/usr/lib/python2.6/site-packages/flask/app.py", line 1344, in dispatch_request
    return self.view_functions[rule.endpoint](**req.view_args)
  File "/tmp/ncpa/agent/listener/server.py", line 41, in config
    redirect(url_for('/error/?%s' % params))
  File "/usr/lib/python2.6/site-packages/flask/helpers.py", line 361, in url_for
    return appctx.app.handle_url_build_error(error, endpoint, values)
  File "/usr/lib/python2.6/site-packages/flask/helpers.py", line 354, in url_for
    force_external=external)
  File "/usr/lib/python2.6/site-packages/werkzeug/routing.py", line 1607, in build
    raise BuildError(endpoint, values, method)
BuildError: ('/error/?msg=items%28%29+takes+at+least+2+arguments+%281+given%29', {}, None)
01/11/13 00:42:31 INFO:192.168.1.28 - - [11/Jan/2013 00:42:31] "GET /config/ HTTP/1.1" 500 -
01/11/13 00:43:25 INFO: * Running on http://0.0.0.0:5692/
01/11/13 00:43:27 ERROR:ConfigParser instance has no attribute '__getitem__'
Traceback (most recent call last):
  File "/tmp/ncpa/agent/listener/server.py", line 36, in config
    return render_template('config.html', **{'config' : listener.config['iconfig']['_sections']})
AttributeError: ConfigParser instance has no attribute '__getitem__'
01/11/13 00:43:27 ERROR:Exception on /config/ [GET]
Traceback (most recent call last):
  File "/usr/lib/python2.6/site-packages/flask/app.py", line 1687, in wsgi_app
    response = self.full_dispatch_request()
  File "/usr/lib/python2.6/site-packages/flask/app.py", line 1360, in full_dispatch_request
    rv = self.handle_user_exception(e)
  File "/usr/lib/python2.6/site-packages/flask/app.py", line 1358, in full_dispatch_request
    rv = self.dispatch_request()
  File "/usr/lib/python2.6/site-packages/flask/app.py", line 1344, in dispatch_request
    return self.view_functions[rule.endpoint](**req.view_args)
  File "/tmp/ncpa/agent/listener/server.py", line 41, in config
    redirect(url_for('/error/?%s' % params))
  File "/usr/lib/python2.6/site-packages/flask/helpers.py", line 361, in url_for
    return appctx.app.handle_url_build_error(error, endpoint, values)
  File "/usr/lib/python2.6/site-packages/flask/helpers.py", line 354, in url_for
    force_external=external)
  File "/usr/lib/python2.6/site-packages/werkzeug/routing.py", line 1607, in build
    raise BuildError(endpoint, values, method)
BuildError: ('/error/?msg=ConfigParser+instance+has+no+attribute+%27__getitem__%27', {}, None)
01/11/13 00:43:27 INFO:192.168.1.28 - - [11/Jan/2013 00:43:27] "GET /config/ HTTP/1.1" 500 -
01/11/13 00:43:50 INFO: * Running on http://0.0.0.0:5692/
01/11/13 00:43:53 INFO:192.168.1.28 - - [11/Jan/2013 00:43:53] "GET /config/ HTTP/1.1" 200 -
01/11/13 00:44:05 INFO:192.168.1.28 - - [11/Jan/2013 00:44:05] "GET /main HTTP/1.1" 404 -
01/11/13 00:44:40 INFO:192.168.1.28 - - [11/Jan/2013 00:44:40] "GET / HTTP/1.1" 200 -
01/11/13 00:44:40 INFO:192.168.1.28 - - [11/Jan/2013 00:44:40] "GET /static/images/ui-bg_flat_75_ffffff_40x100.png HTTP/1.1" 404 -
01/11/13 00:44:40 INFO:192.168.1.28 - - [11/Jan/2013 00:44:40] "GET /static/images/ui-bg_highlight-soft_75_cccccc_1x100.png HTTP/1.1" 404 -
01/11/13 00:44:40 INFO:192.168.1.28 - - [11/Jan/2013 00:44:40] "GET /static/images/ui-bg_glass_75_e6e6e6_1x400.png HTTP/1.1" 404 -
01/11/13 00:44:40 INFO:192.168.1.28 - - [11/Jan/2013 00:44:40] "GET /static/images/ui-bg_glass_65_ffffff_1x400.png HTTP/1.1" 404 -
01/11/13 00:44:41 INFO:192.168.1.28 - - [11/Jan/2013 00:44:41] "GET /config/ HTTP/1.1" 200 -
01/11/13 00:44:43 INFO:192.168.1.28 - - [11/Jan/2013 00:44:43] "GET /static/images/ui-bg_glass_75_dadada_1x400.png HTTP/1.1" 404 -
01/11/13 00:58:31 ERROR:Exception on /command/ [GET]
Traceback (most recent call last):
  File "/usr/lib/python2.6/site-packages/flask/app.py", line 1687, in wsgi_app
    response = self.full_dispatch_request()
  File "/usr/lib/python2.6/site-packages/flask/app.py", line 1360, in full_dispatch_request
    rv = self.handle_user_exception(e)
  File "/usr/lib/python2.6/site-packages/flask/app.py", line 1358, in full_dispatch_request
    rv = self.dispatch_request()
  File "/usr/lib/python2.6/site-packages/flask/app.py", line 1344, in dispatch_request
    return self.view_functions[rule.endpoint](**req.view_args)
  File "/tmp/ncpa/agent/listener/server.py", line 54, in command
    params = urllib.urlencode({'msg' : str(e)})
UnboundLocalError: local variable 'generic' referenced before assignment
01/11/13 00:58:31 INFO:192.168.1.28 - - [11/Jan/2013 00:58:31] "GET /command/ HTTP/1.1" 500 -
01/11/13 01:00:59 INFO: * Running on http://0.0.0.0:5692/
01/11/13 01:01:03 ERROR:Exception on /command/ [GET]
Traceback (most recent call last):
  File "/usr/lib/python2.6/site-packages/flask/app.py", line 1687, in wsgi_app
    response = self.full_dispatch_request()
  File "/usr/lib/python2.6/site-packages/flask/app.py", line 1360, in full_dispatch_request
    rv = self.handle_user_exception(e)
  File "/usr/lib/python2.6/site-packages/flask/app.py", line 1358, in full_dispatch_request
    rv = self.dispatch_request()
  File "/usr/lib/python2.6/site-packages/flask/app.py", line 1344, in dispatch_request
    return self.view_functions[rule.endpoint](**req.view_args)
  File "/tmp/ncpa/agent/listener/server.py", line 57, in command
    return generic(request)
UnboundLocalError: local variable 'generic' referenced before assignment
01/11/13 01:01:03 INFO:192.168.1.28 - - [11/Jan/2013 01:01:03] "GET /command/ HTTP/1.1" 500 -
01/11/13 01:01:51 INFO: * Running on http://0.0.0.0:5692/
01/11/13 01:01:55 ERROR:'module' object has no attribute ''
Traceback (most recent call last):
  File "/tmp/ncpa/agent/listener/server.py", line 52, in command
    generic = getattr(commands, command)
AttributeError: 'module' object has no attribute ''
01/11/13 01:01:55 INFO:192.168.1.28 - - [11/Jan/2013 01:01:55] "GET /command/ HTTP/1.1" 302 -
01/11/13 01:01:55 INFO:192.168.1.28 - - [11/Jan/2013 01:01:55] "GET /error/?msg=%27module%27+object+has+no+attribute+%27%27 HTTP/1.1" 200 -
01/11/13 01:03:18 INFO: * Running on http://0.0.0.0:5692/
01/11/13 01:03:21 ERROR:Exception on /error/ [GET]
Traceback (most recent call last):
  File "/usr/lib/python2.6/site-packages/flask/app.py", line 1687, in wsgi_app
    response = self.full_dispatch_request()
  File "/usr/lib/python2.6/site-packages/flask/app.py", line 1360, in full_dispatch_request
    rv = self.handle_user_exception(e)
  File "/usr/lib/python2.6/site-packages/flask/app.py", line 1358, in full_dispatch_request
    rv = self.dispatch_request()
  File "/usr/lib/python2.6/site-packages/flask/app.py", line 1344, in dispatch_request
    return self.view_functions[rule.endpoint](**req.view_args)
  File "/tmp/ncpa/agent/listener/server.py", line 26, in error
    return jsonfiy(error=msg)
NameError: global name 'jsonfiy' is not defined
01/11/13 01:03:21 INFO:192.168.1.28 - - [11/Jan/2013 01:03:21] "GET /error/?msg=%27module%27+object+has+no+attribute+%27%27 HTTP/1.1" 500 -
01/11/13 01:04:01 INFO: * Running on http://0.0.0.0:5692/
01/11/13 01:04:07 INFO:192.168.1.28 - - [11/Jan/2013 01:04:07] "GET / HTTP/1.1" 200 -
01/11/13 01:04:08 INFO:192.168.1.28 - - [11/Jan/2013 01:04:08] "GET /static/images/ui-bg_flat_75_ffffff_40x100.png HTTP/1.1" 404 -
01/11/13 01:04:08 INFO:192.168.1.28 - - [11/Jan/2013 01:04:08] "GET /static/images/ui-bg_highlight-soft_75_cccccc_1x100.png HTTP/1.1" 404 -
01/11/13 01:04:08 INFO:192.168.1.28 - - [11/Jan/2013 01:04:08] "GET /static/images/ui-bg_glass_75_e6e6e6_1x400.png HTTP/1.1" 404 -
01/11/13 01:04:08 INFO:192.168.1.28 - - [11/Jan/2013 01:04:08] "GET /static/images/ui-bg_glass_65_ffffff_1x400.png HTTP/1.1" 404 -
01/11/13 01:04:08 INFO:192.168.1.28 - - [11/Jan/2013 01:04:08] "GET /config/ HTTP/1.1" 200 -
01/11/13 01:04:18 ERROR:'module' object has no attribute ''
Traceback (most recent call last):
  File "/tmp/ncpa/agent/listener/server.py", line 51, in command
    generic = getattr(commands, command)
AttributeError: 'module' object has no attribute ''
01/11/13 01:04:18 INFO:192.168.1.28 - - [11/Jan/2013 01:04:18] "GET /command/ HTTP/1.1" 302 -
01/11/13 01:04:18 INFO:192.168.1.28 - - [11/Jan/2013 01:04:18] "GET /error/?msg=%27module%27+object+has+no+attribute+%27%27 HTTP/1.1" 200 -
01/11/13 01:06:05 INFO: * Running on http://0.0.0.0:5692/
01/11/13 01:06:16 ERROR:'Request' object has no attribute 'REQUEST'
Traceback (most recent call last):
  File "/tmp/ncpa/agent/listener/server.py", line 31, in check
    processor.check_metric(request.REQUEST, config['inconfig'])
  File "/usr/lib/python2.6/site-packages/werkzeug/local.py", line 336, in __getattr__
    return getattr(self._get_current_object(), name)
AttributeError: 'Request' object has no attribute 'REQUEST'
01/11/13 01:06:16 INFO:192.168.1.28 - - [11/Jan/2013 01:06:16] "GET /check?metric=check_cpu HTTP/1.1" 302 -
01/11/13 01:06:16 INFO:192.168.1.28 - - [11/Jan/2013 01:06:16] "GET /error/?msg=%27Request%27+object+has+no+attribute+%27REQUEST%27 HTTP/1.1" 200 -
01/11/13 01:06:36 INFO: * Running on http://0.0.0.0:5692/
01/11/13 01:06:42 ERROR:'function' object is unsubscriptable
Traceback (most recent call last):
  File "/tmp/ncpa/agent/listener/server.py", line 31, in check
    processor.check_metric(request.args, config['inconfig'])
TypeError: 'function' object is unsubscriptable
01/11/13 01:06:42 INFO:192.168.1.28 - - [11/Jan/2013 01:06:42] "GET /check?metric=check_cpu HTTP/1.1" 302 -
01/11/13 01:06:42 INFO:192.168.1.28 - - [11/Jan/2013 01:06:42] "GET /error/?msg=%27function%27+object+is+unsubscriptable HTTP/1.1" 200 -
01/11/13 01:07:16 INFO: * Running on http://0.0.0.0:5692/
01/11/13 01:07:24 ERROR:'function' object is unsubscriptable
Traceback (most recent call last):
  File "/tmp/ncpa/agent/listener/server.py", line 31, in check
    processor.check_metric(request.args, config['iconfig'])
TypeError: 'function' object is unsubscriptable
01/11/13 01:07:24 INFO:192.168.1.28 - - [11/Jan/2013 01:07:24] "GET /check?metric=check_cpu HTTP/1.1" 302 -
01/11/13 01:07:24 INFO:192.168.1.28 - - [11/Jan/2013 01:07:24] "GET /error/?msg=%27function%27+object+is+unsubscriptable HTTP/1.1" 200 -
01/11/13 01:07:57 INFO:192.168.1.28 - - [11/Jan/2013 01:07:57] "GET /error/?msg=%27function%27+object+is+unsubscriptable HTTP/1.1" 200 -
01/11/13 01:08:02 ERROR:'function' object is unsubscriptable
Traceback (most recent call last):
  File "/tmp/ncpa/agent/listener/server.py", line 31, in check
    processor.check_metric(request.args, listener.config['iconfig'])
TypeError: 'function' object is unsubscriptable
01/11/13 01:08:02 INFO:192.168.1.28 - - [11/Jan/2013 01:08:02] "GET /check?metric=check_cpu HTTP/1.1" 302 -
01/11/13 01:08:02 INFO:192.168.1.28 - - [11/Jan/2013 01:08:02] "GET /error/?msg=%27function%27+object+is+unsubscriptable HTTP/1.1" 200 -
01/11/13 01:08:09 INFO: * Running on http://0.0.0.0:5692/
01/11/13 01:08:15 DEBUG:Beginning execution for check_cpu
01/11/13 01:08:15 ERROR:Exception on /check [GET]
Traceback (most recent call last):
  File "/usr/lib/python2.6/site-packages/flask/app.py", line 1687, in wsgi_app
    response = self.full_dispatch_request()
  File "/usr/lib/python2.6/site-packages/flask/app.py", line 1361, in full_dispatch_request
    response = self.make_response(rv)
  File "/usr/lib/python2.6/site-packages/flask/app.py", line 1439, in make_response
    raise ValueError('View function did not return a response')
ValueError: View function did not return a response
01/11/13 01:08:15 INFO:192.168.1.28 - - [11/Jan/2013 01:08:15] "GET /check?metric=check_cpu HTTP/1.1" 500 -
01/11/13 01:08:35 DEBUG:Beginning execution for check_cpu
01/11/13 01:08:35 ERROR:Exception on /check [GET]
Traceback (most recent call last):
  File "/usr/lib/python2.6/site-packages/flask/app.py", line 1687, in wsgi_app
    response = self.full_dispatch_request()
  File "/usr/lib/python2.6/site-packages/flask/app.py", line 1361, in full_dispatch_request
    response = self.make_response(rv)
  File "/usr/lib/python2.6/site-packages/flask/app.py", line 1439, in make_response
    raise ValueError('View function did not return a response')
ValueError: View function did not return a response
01/11/13 01:08:35 INFO:192.168.1.28 - - [11/Jan/2013 01:08:35] "GET /check?metric=check_cpu HTTP/1.1" 500 -
01/11/13 01:08:44 INFO: * Running on http://0.0.0.0:5692/
01/11/13 01:08:46 DEBUG:Beginning execution for check_cpu
01/11/13 01:08:46 INFO:192.168.1.28 - - [11/Jan/2013 01:08:46] "GET /check?metric=check_cpu HTTP/1.1" 200 -
01/11/13 01:11:20 INFO: * Running on http://0.0.0.0:5692/
01/11/13 01:11:26 DEBUG:Beginning execution for check_cpu
01/11/13 01:11:26 INFO:192.168.1.28 - - [11/Jan/2013 01:11:26] "GET /check?metric=check_cpu HTTP/1.1" 200 -
01/11/13 01:22:14 INFO: * Running on http://0.0.0.0:5692/
01/11/13 01:22:49 INFO:192.168.1.28 - - [11/Jan/2013 01:22:49] "GET /nrdp/?cmd=whatup&token=a HTTP/1.1" 404 -
01/11/13 01:23:33 INFO: * Running on http://0.0.0.0:5692/
01/11/13 01:23:37 INFO:192.168.1.28 - - [11/Jan/2013 01:23:37] "GET /nrdp/?cmd=whatup&token=a HTTP/1.1" 404 -
01/11/13 01:24:15 ERROR:global name 'listner' is not defined
Traceback (most recent call last):
  File "/tmp/ncpa/agent/listener/server.py", line 41, in nrdp
    forward_to = listner.config['iconfig'].get('nrdp', 'parent')
NameError: global name 'listner' is not defined
01/11/13 01:24:15 INFO:192.168.1.28 - - [11/Jan/2013 01:24:15] "GET /nrdp?cmd=whatup&token=a HTTP/1.1" 302 -
01/11/13 01:24:15 INFO:192.168.1.28 - - [11/Jan/2013 01:24:15] "GET /error?msg=global+name+%27listner%27+is+not+defined HTTP/1.1" 200 -
01/11/13 01:24:30 INFO:192.168.1.28 - - [11/Jan/2013 01:24:30] "GET /error?msg=global+name+%27listner%27+is+not+defined HTTP/1.1" 200 -
01/11/13 01:25:02 INFO: * Running on http://0.0.0.0:5692/
01/11/13 01:25:11 INFO:192.168.1.28 - - [11/Jan/2013 01:25:11] "GET /nrdp/?cmd=whatup&token=a HTTP/1.1" 404 -
01/11/13 01:26:40 INFO:192.168.1.28 - - [11/Jan/2013 01:26:40] "GET /nrdp/?cmd=whatup&token=a HTTP/1.1" 404 -
01/11/13 01:27:32 INFO: * Running on http://0.0.0.0:5692/
01/11/13 01:27:36 INFO:192.168.1.28 - - [11/Jan/2013 01:27:36] "GET /nrdp/?cmd=whatup&token=a HTTP/1.1" 404 -
01/11/13 01:28:38 INFO: * Running on http://0.0.0.0:5692/
01/11/13 01:28:38 INFO: * Restarting with reloader
01/11/13 01:28:43 INFO:192.168.1.28 - - [11/Jan/2013 01:28:43] "GET /nrdp/?cmd=whatup&token=a HTTP/1.1" 404 -
01/11/13 01:29:18 INFO: * Detected change in '/tmp/ncpa/agent/listener/server.py', reloading
01/11/13 01:29:23 INFO: * Running on http://0.0.0.0:5692/
01/11/13 01:29:23 INFO: * Restarting with reloader
01/11/13 01:29:27 INFO:192.168.1.28 - - [11/Jan/2013 01:29:27] "GET /nrdp/?cmd=whatup&token=a HTTP/1.1" 404 -
01/11/13 01:29:32 INFO:192.168.1.28 - - [11/Jan/2013 01:29:32] "GET /nrdp/?cmd=whatup&token=a HTTP/1.1" 404 -
01/11/13 01:29:35 INFO:192.168.1.28 - - [11/Jan/2013 01:29:35] "GET /nrdp/?cmd=whatup&token=a HTTP/1.1" 404 -
01/11/13 01:30:49 INFO: * Detected change in '/tmp/ncpa/agent/listener/server.py', reloading
01/11/13 01:31:00 INFO: * Running on http://0.0.0.0:5692/
01/11/13 01:31:00 INFO: * Restarting with reloader
01/11/13 01:31:03 INFO:192.168.1.28 - - [11/Jan/2013 01:31:03] "GET /nrdp/?cmd=whatup&token=a HTTP/1.1" 404 -
01/11/13 01:32:06 INFO: * Running on http://0.0.0.0:5692/
01/11/13 01:32:06 INFO: * Restarting with reloader
01/11/13 01:32:10 INFO:192.168.1.28 - - [11/Jan/2013 01:32:10] "GET /nrdp/?cmd=whatup&token=a HTTP/1.1" 404 -
01/11/13 01:32:41 INFO: * Detected change in '/tmp/ncpa/agent/listener/server.py', reloading
01/11/13 01:32:49 INFO: * Running on http://0.0.0.0:5692/
01/11/13 01:32:49 INFO: * Restarting with reloader
01/11/13 01:32:52 INFO:192.168.1.28 - - [11/Jan/2013 01:32:52] "GET /nrdp/?cmd=whatup&token=a HTTP/1.1" 404 -
01/11/13 01:33:10 WARNING:http://192.168.1.26/nrdp
01/11/13 01:33:10 ERROR:'Request' object has no attribute 'post'
Traceback (most recent call last):
  File "/tmp/ncpa/agent/listener/server.py", line 46, in nrdp
    response = requests.post(forward_to, params=request.post)
  File "/usr/lib/python2.6/site-packages/werkzeug/local.py", line 336, in __getattr__
    return getattr(self._get_current_object(), name)
AttributeError: 'Request' object has no attribute 'post'
01/11/13 01:33:10 INFO:192.168.1.28 - - [11/Jan/2013 01:33:10] "GET /nrdp?cmd=whatup&token=a HTTP/1.1" 302 -
01/11/13 01:33:10 INFO:192.168.1.28 - - [11/Jan/2013 01:33:10] "GET /error?msg=%27Request%27+object+has+no+attribute+%27post%27 HTTP/1.1" 200 -
01/11/13 01:34:08 INFO: * Detected change in '/tmp/ncpa/agent/listener/server.py', reloading
01/11/13 01:34:13 INFO: * Running on http://0.0.0.0:5692/
01/11/13 01:34:13 INFO: * Restarting with reloader
01/11/13 01:34:21 WARNING:http://192.168.1.26/nrdp
01/11/13 01:34:21 INFO:Starting new HTTP connection (1): 192.168.1.26
01/11/13 01:34:21 DEBUG:"POST /nrdp?token=a&cmd=whatup HTTP/1.1" 301 334
01/11/13 01:34:21 DEBUG:"POST /nrdp/?token=a&cmd=whatup&token=a&cmd=whatup HTTP/1.1" 200 18
01/11/13 01:34:21 INFO:192.168.1.28 - - [11/Jan/2013 01:34:21] "GET /nrdp?cmd=whatup&token=a HTTP/1.1" 200 -
01/11/13 01:35:00 WARNING:http://192.168.1.26/nrdp
01/11/13 01:35:00 INFO:Starting new HTTP connection (1): 192.168.1.26
01/11/13 01:35:00 DEBUG:"POST /nrdp?token=a&cmd=updatenrds HTTP/1.1" 301 338
01/11/13 01:35:00 DEBUG:"POST /nrdp/?token=a&cmd=updatenrds&token=a&cmd=updatenrds HTTP/1.1" 200 109
01/11/13 01:35:00 INFO:192.168.1.28 - - [11/Jan/2013 01:35:00] "GET /nrdp?cmd=updatenrds&token=a HTTP/1.1" 200 -
01/11/13 01:35:54 INFO: * Detected change in '/tmp/ncpa/agent/listener/server.py', reloading
01/11/13 01:36:00 INFO: * Running on http://0.0.0.0:5692/
01/11/13 01:36:00 INFO: * Restarting with reloader
01/11/13 01:36:05 WARNING:http://192.168.1.26/nrdp
01/11/13 01:36:05 INFO:Starting new HTTP connection (1): 192.168.1.26
01/11/13 01:36:05 DEBUG:"POST /nrdp?token=a&cmd=updatenrds HTTP/1.1" 301 338
01/11/13 01:36:05 DEBUG:"POST /nrdp/?token=a&cmd=updatenrds&token=a&cmd=updatenrds HTTP/1.1" 200 109
01/11/13 01:36:05 ERROR:'Response' object is unsubscriptable
Traceback (most recent call last):
  File "/tmp/ncpa/agent/listener/server.py", line 48, in nrdp
    resp['Content-type'] = response['Content-type']
TypeError: 'Response' object is unsubscriptable
01/11/13 01:36:05 INFO:192.168.1.28 - - [11/Jan/2013 01:36:05] "GET /nrdp?cmd=updatenrds&token=a HTTP/1.1" 302 -
01/11/13 01:36:05 INFO:192.168.1.28 - - [11/Jan/2013 01:36:05] "GET /error?msg=%27Response%27+object+is+unsubscriptable HTTP/1.1" 200 -
01/11/13 01:37:16 INFO: * Detected change in '/tmp/ncpa/agent/listener/server.py', reloading
01/11/13 01:37:21 INFO: * Running on http://0.0.0.0:5692/
01/11/13 01:37:21 INFO: * Restarting with reloader
01/11/13 01:37:31 INFO:192.168.1.28 - - [11/Jan/2013 01:37:31] "GET /nrdp/?cmd=true&boo=false HTTP/1.1" 404 -
01/11/13 01:37:55 INFO: * Detected change in '/tmp/ncpa/agent/listener/server.py', reloading
01/11/13 01:38:53 INFO: * Running on http://0.0.0.0:5692/
01/11/13 01:38:53 INFO: * Restarting with reloader
01/11/13 01:38:57 INFO:192.168.1.28 - - [11/Jan/2013 01:38:57] "GET /nrdp/?cmd=true&boo=false HTTP/1.1" 404 -
01/11/13 01:41:36 INFO: * Detected change in '/tmp/ncpa/agent/listener/server.py', reloading
01/11/13 01:41:40 INFO: * Running on http://0.0.0.0:5692/
01/11/13 01:41:40 INFO: * Restarting with reloader
01/11/13 01:41:44 INFO:192.168.1.28 - - [11/Jan/2013 01:41:44] "GET /nrdp/?cmd=true&boo=false HTTP/1.1" 404 -
01/11/13 01:43:37 INFO: * Detected change in '/tmp/ncpa/agent/listener/server.py', reloading
01/11/13 01:44:18 INFO: * Running on http://0.0.0.0:5692/
01/11/13 01:44:18 INFO: * Restarting with reloader
01/11/13 01:44:21 INFO:192.168.1.28 - - [11/Jan/2013 01:44:21] "GET /nrdp/?cmd=true&boo=false HTTP/1.1" 404 -
01/11/13 01:44:43 INFO: * Detected change in '/tmp/ncpa/agent/listener/server.py', reloading
01/11/13 01:44:51 INFO: * Running on http://0.0.0.0:5692/
01/11/13 01:44:51 INFO: * Restarting with reloader
01/11/13 01:44:54 INFO:192.168.1.28 - - [11/Jan/2013 01:44:54] "GET /nrdp/?cmd=true&boo=false HTTP/1.1" 404 -
01/11/13 01:47:35 INFO: * Detected change in '/tmp/ncpa/agent/listener/server.py', reloading
01/11/13 01:47:40 INFO: * Running on http://0.0.0.0:5692/
01/11/13 01:47:40 INFO: * Restarting with reloader
01/11/13 01:47:44 INFO:192.168.1.28 - - [11/Jan/2013 01:47:44] "GET /nrdp/?cmd=true&boo=false HTTP/1.1" 404 -
01/11/13 01:48:47 INFO:192.168.1.28 - - [11/Jan/2013 01:48:47] "GET /commands HTTP/1.1" 404 -
01/11/13 01:48:54 INFO:192.168.1.28 - - [11/Jan/2013 01:48:54] "GET /command?command=enumerate_plugins HTTP/1.1" 200 -
01/11/13 01:49:02 WARNING:http://192.168.1.26/nrdp
01/11/13 01:49:02 INFO:Starting new HTTP connection (1): 192.168.1.26
01/11/13 01:49:02 DEBUG:"POST /nrdp?token=a&cmd=whatup HTTP/1.1" 301 334
01/11/13 01:49:02 DEBUG:"POST /nrdp/?token=a&cmd=whatup&token=a&cmd=whatup HTTP/1.1" 200 18
01/11/13 01:49:02 INFO:192.168.1.28 - - [11/Jan/2013 01:49:02] "GET /nrdp?cmd=whatup&token=a HTTP/1.1" 200 -
01/11/13 01:49:27 INFO: * Detected change in '/tmp/ncpa/agent/listener/server.py', reloading
01/11/13 01:49:32 INFO: * Running on http://0.0.0.0:5692/
01/11/13 01:49:32 INFO: * Restarting with reloader
01/11/13 01:49:36 WARNING:http://192.168.1.26/nrdp
01/11/13 01:49:36 INFO:Starting new HTTP connection (1): 192.168.1.26
01/11/13 01:49:36 DEBUG:"POST /nrdp?token=a&cmd=whatup HTTP/1.1" 301 334
01/11/13 01:49:36 DEBUG:"POST /nrdp/?token=a&cmd=whatup&token=a&cmd=whatup HTTP/1.1" 200 18
01/11/13 01:49:36 ERROR:make_response() got an unexpected keyword argument 'mimetype'
Traceback (most recent call last):
  File "/tmp/ncpa/agent/listener/server.py", line 47, in nrdp
    return make_response(response.content, 200, mimetype='text/xml')
TypeError: make_response() got an unexpected keyword argument 'mimetype'
01/11/13 01:49:36 INFO:192.168.1.28 - - [11/Jan/2013 01:49:36] "GET /nrdp?cmd=whatup&token=a HTTP/1.1" 302 -
01/11/13 01:49:36 INFO:192.168.1.28 - - [11/Jan/2013 01:49:36] "GET /error?msg=make_response%28%29+got+an+unexpected+keyword+argument+%27mimetype%27 HTTP/1.1" 200 -
01/11/13 01:50:27 INFO: * Detected change in '/tmp/ncpa/agent/listener/server.py', reloading
01/11/13 01:50:33 INFO: * Running on http://0.0.0.0:5692/
01/11/13 01:50:33 INFO: * Restarting with reloader
01/11/13 01:50:40 WARNING:http://192.168.1.26/nrdp
01/11/13 01:50:40 INFO:Starting new HTTP connection (1): 192.168.1.26
01/11/13 01:50:40 DEBUG:"POST /nrdp?token=a&cmd=whatup HTTP/1.1" 301 334
01/11/13 01:50:40 DEBUG:"POST /nrdp/?token=a&cmd=whatup&token=a&cmd=whatup HTTP/1.1" 200 18
01/11/13 01:50:40 ERROR:'Response' object does not support item assignment
Traceback (most recent call last):
  File "/tmp/ncpa/agent/listener/server.py", line 48, in nrdp
    resp['content-type'] = response.headers['content-type']
TypeError: 'Response' object does not support item assignment
01/11/13 01:50:40 INFO:192.168.1.28 - - [11/Jan/2013 01:50:40] "GET /nrdp?cmd=whatup&token=a HTTP/1.1" 302 -
01/11/13 01:50:40 INFO:192.168.1.28 - - [11/Jan/2013 01:50:40] "GET /error?msg=%27Response%27+object+does+not+support+item+assignment HTTP/1.1" 200 -
01/11/13 01:52:29 INFO: * Detected change in '/tmp/ncpa/agent/listener/server.py', reloading
01/11/13 01:52:45 INFO: * Running on http://0.0.0.0:5692/
01/11/13 01:52:45 INFO: * Restarting with reloader
01/11/13 01:52:56 WARNING:http://192.168.1.26/nrdp
01/11/13 01:52:56 INFO:Starting new HTTP connection (1): 192.168.1.26
01/11/13 01:52:56 DEBUG:"POST /nrdp?token=a&cmd=whatup HTTP/1.1" 301 334
01/11/13 01:52:56 DEBUG:"POST /nrdp/?token=a&cmd=whatup&token=a&cmd=whatup HTTP/1.1" 200 18
01/11/13 01:52:56 ERROR:make_response() got an unexpected keyword argument 'content_type'
Traceback (most recent call last):
  File "/tmp/ncpa/agent/listener/server.py", line 47, in nrdp
    resp = make_response(response.content, 200, content_type=response.headers['content-type'])
TypeError: make_response() got an unexpected keyword argument 'content_type'
01/11/13 01:52:56 INFO:192.168.1.28 - - [11/Jan/2013 01:52:56] "GET /nrdp?cmd=whatup&token=a HTTP/1.1" 302 -
01/11/13 01:52:56 INFO:192.168.1.28 - - [11/Jan/2013 01:52:56] "GET /error?msg=make_response%28%29+got+an+unexpected+keyword+argument+%27content_type%27 HTTP/1.1" 200 -
01/11/13 01:53:40 INFO: * Detected change in '/tmp/ncpa/agent/listener/server.py', reloading
01/11/13 01:53:45 INFO: * Running on http://0.0.0.0:5692/
01/11/13 01:53:45 INFO: * Restarting with reloader
01/11/13 01:53:52 WARNING:http://192.168.1.26/nrdp
01/11/13 01:53:52 INFO:Starting new HTTP connection (1): 192.168.1.26
01/11/13 01:53:52 DEBUG:"POST /nrdp?token=a&cmd=whatup HTTP/1.1" 301 334
01/11/13 01:53:52 DEBUG:"POST /nrdp/?token=a&cmd=whatup&token=a&cmd=whatup HTTP/1.1" 200 18
01/11/13 01:53:52 ERROR:make_response() got an unexpected keyword argument 'mimetype'
Traceback (most recent call last):
  File "/tmp/ncpa/agent/listener/server.py", line 47, in nrdp
    resp = make_response(response.content, 200, mimetype=response.headers['content-type'])
TypeError: make_response() got an unexpected keyword argument 'mimetype'
01/11/13 01:53:52 INFO:192.168.1.28 - - [11/Jan/2013 01:53:52] "GET /nrdp?cmd=whatup&token=a HTTP/1.1" 302 -
01/11/13 01:53:52 INFO:192.168.1.28 - - [11/Jan/2013 01:53:52] "GET /error?msg=make_response%28%29+got+an+unexpected+keyword+argument+%27mimetype%27 HTTP/1.1" 200 -
01/11/13 01:54:58 INFO: * Detected change in '/tmp/ncpa/agent/listener/server.py', reloading
01/11/13 01:55:03 INFO: * Running on http://0.0.0.0:5692/
01/11/13 01:55:03 INFO: * Restarting with reloader
01/11/13 01:55:12 WARNING:http://192.168.1.26/nrdp
01/11/13 01:55:12 INFO:Starting new HTTP connection (1): 192.168.1.26
01/11/13 01:55:12 DEBUG:"POST /nrdp?token=a&cmd=whatup HTTP/1.1" 301 334
01/11/13 01:55:12 DEBUG:"POST /nrdp/?token=a&cmd=whatup&token=a&cmd=whatup HTTP/1.1" 200 18
01/11/13 01:55:12 ERROR:global name 'Response' is not defined
Traceback (most recent call last):
  File "/tmp/ncpa/agent/listener/server.py", line 47, in nrdp
    resp = Response(response.content, 200, content_type=response.headers['content-type'])
NameError: global name 'Response' is not defined
01/11/13 01:55:12 INFO:192.168.1.28 - - [11/Jan/2013 01:55:12] "GET /nrdp?cmd=whatup&token=a HTTP/1.1" 302 -
01/11/13 01:55:12 INFO:192.168.1.28 - - [11/Jan/2013 01:55:12] "GET /error?msg=global+name+%27Response%27+is+not+defined HTTP/1.1" 200 -
01/11/13 01:55:21 INFO: * Detected change in '/tmp/ncpa/agent/listener/server.py', reloading
01/11/13 01:55:25 INFO: * Running on http://0.0.0.0:5692/
01/11/13 01:55:25 INFO: * Restarting with reloader
01/11/13 01:55:33 WARNING:http://192.168.1.26/nrdp
01/11/13 01:55:33 INFO:Starting new HTTP connection (1): 192.168.1.26
01/11/13 01:55:33 DEBUG:"POST /nrdp?token=a&cmd=whatup HTTP/1.1" 301 334
01/11/13 01:55:33 DEBUG:"POST /nrdp/?token=a&cmd=whatup&token=a&cmd=whatup HTTP/1.1" 200 18
01/11/13 01:55:33 INFO:192.168.1.28 - - [11/Jan/2013 01:55:33] "GET /nrdp?cmd=whatup&token=a HTTP/1.1" 200 -
01/11/13 01:55:46 INFO: * Detected change in '/tmp/ncpa/agent/listener/server.py', reloading
01/11/13 01:55:50 INFO: * Running on http://0.0.0.0:5692/
01/11/13 01:55:50 INFO: * Restarting with reloader
01/11/13 01:55:53 WARNING:http://192.168.1.26/nrdp
01/11/13 01:55:53 INFO:Starting new HTTP connection (1): 192.168.1.26
01/11/13 01:55:53 DEBUG:"POST /nrdp?token=a&cmd=whatup HTTP/1.1" 301 334
01/11/13 01:55:53 DEBUG:"POST /nrdp/?token=a&cmd=whatup&token=a&cmd=whatup HTTP/1.1" 200 18
01/11/13 01:55:53 INFO:192.168.1.28 - - [11/Jan/2013 01:55:53] "GET /nrdp?cmd=whatup&token=a HTTP/1.1" 200 -
01/11/13 01:56:07 WARNING:http://192.168.1.26/nrdp
01/11/13 01:56:07 INFO:Starting new HTTP connection (1): 192.168.1.26
01/11/13 01:56:07 DEBUG:"POST /nrdp HTTP/1.1" 301 311
01/11/13 01:56:07 DEBUG:"POST /nrdp/ HTTP/1.1" 200 1243
01/11/13 01:56:07 INFO:192.168.1.28 - - [11/Jan/2013 01:56:07] "GET /nrdp HTTP/1.1" 200 -
01/11/13 07:57:49 DEBUG:Parsing config...
01/11/13 07:57:49 DEBUG:Parsing commands...
01/11/13 07:57:49 DEBUG:Parsing new individual command.
01/11/13 07:57:49 DEBUG:Setting hostname to localhost and servicename to __host__
01/11/13 07:57:49 DEBUG:Parsing command: check_swap
01/11/13 07:57:49 DEBUG:Command did not contain arguments. Single directive.
01/11/13 07:57:49 DEBUG:Nagios Hostname: localhost -- Nagios Servicename: __host__ -- Command: check_swap -- Arguments: None -- Stdout: None -- Return Code: None
01/11/13 07:57:49 DEBUG:Parsing new individual command.
01/11/13 07:57:49 DEBUG:Setting hostname to localhost and servicename to cpu usage
01/11/13 07:57:49 DEBUG:Parsing command: check_cpu
01/11/13 07:57:49 DEBUG:Command did not contain arguments. Single directive.
01/11/13 07:57:49 DEBUG:Nagios Hostname: localhost -- Nagios Servicename: cpu usage -- Command: check_cpu -- Arguments: None -- Stdout: None -- Return Code: None
01/11/13 07:57:49 DEBUG:Parsing new individual command.
01/11/13 07:57:49 DEBUG:Setting hostname to localhost and servicename to memory usage
01/11/13 07:57:49 DEBUG:Parsing command: check_memory
01/11/13 07:57:49 DEBUG:Command did not contain arguments. Single directive.
01/11/13 07:57:49 DEBUG:Nagios Hostname: localhost -- Nagios Servicename: memory usage -- Command: check_memory -- Arguments: None -- Stdout: None -- Return Code: None
01/11/13 07:57:49 DEBUG:Establishing Nagios handler...
01/11/13 07:57:49 DEBUG:Nagios handler established.
01/11/13 07:57:49 INFO:Starting new HTTP connection (1): 192.168.1.26
01/11/13 07:57:49 DEBUG:"GET /nrdp?token=a&cmd=getconfig&os=chinook&configname=ncpa HTTP/1.1" 301 372
01/11/13 07:57:49 DEBUG:"GET /nrdp/?token=a&cmd=getconfig&os=chinook&configname=ncpa&token=a&cmd=getconfig&os=chinook&configname=ncpa HTTP/1.1" 404 0
01/11/13 07:57:49 DEBUG:hitting url with payload: http://192.168.1.26/nrdp/?token=a&cmd=getconfig&os=chinook&configname=ncpa&token=a&cmd=getconfig&os=chinook&configname=ncpa
01/11/13 07:57:49 DEBUG:content response from payload: 
01/11/13 07:57:49 DEBUG:URL I am requesting: http://192.168.1.26/nrdp/?token=a&cmd=getconfig&os=chinook&configname=ncpa&token=a&cmd=getconfig&os=chinook&configname=ncpa
01/11/13 07:57:49 DEBUG:Content returned: 
01/11/13 07:57:49 DEBUG:plugin directives I know about: check_cpu
01/11/13 07:57:49 DEBUG:plugin directives I know about: check_memory
01/11/13 07:57:49 DEBUG:plugin directives I know about: check_swap
01/11/13 07:57:49 INFO:Starting new HTTP connection (1): 127.0.0.1
01/11/13 07:57:49 DEBUG:"GET /?command=enumerate_plugins HTTP/1.1" 200 1066
01/11/13 07:57:49 DEBUG:hitting url with payload: http://127.0.0.1:5692/?command=enumerate_plugins
01/11/13 07:57:49 DEBUG:content response from payload: <html>
    <head>
        <link rel='stylesheet' href='/static/chinook.css' />
        <link rel='stylesheet' href='/static/jquery-ui.css' />
        <script src='/static/jquery-1.8.3.min.js'></script>
        <script src='/static/jquery-ui.js'></script>
        <script>
            $(document).ready(function() {
                $('#tabs').tabs();
                $('#config').load('/config')
            });
        </script>
    </head>
    <body>
        <div id='bodywrapper'>
            

            
<div id='tabs'>
    <ul>
        <li><a href='#system'>System Info</a></li>
        <li><a href='#network'>Network Surrounding</a></li>
        <li><a href='#config'>Config</a></li>
    </ul>
    <div id='#system'>
        <div id='system'>
            System stuff will go here
        </div>
    </div>
    <div id='#network'>
        <div id='network'>
            Nmap and latest neighbors
        </div>
    </div>
    <div id='#config'>
        <div id='config'>
            Config
        </div>
    </div>
</div>

        </div>
    </body>
</html>
01/11/13 08:03:23 WARNING:User attempted to restart, var/ncpa_listener.pid still exists, exiting.
01/11/13 08:03:58 INFO: * Running on http://0.0.0.0:5692/
01/11/13 08:03:58 ERROR:[Errno 98] Address already in use
Traceback (most recent call last):
  File "/home/yribbens/Desktop/svn/Projects/ncpa/agent/daemons/posix.py", line 178, in start
    listener.server.listener.run(address, port)
  File "/usr/lib/python2.7/site-packages/flask/app.py", line 739, in run
    run_simple(host, port, self, **options)
  File "/usr/lib/python2.7/site-packages/werkzeug/serving.py", line 613, in run_simple
    test_socket.bind((hostname, port))
  File "/usr/lib/python2.7/socket.py", line 224, in meth
    return getattr(self._sock,name)(*args)
error: [Errno 98] Address already in use
01/11/13 08:04:20 DEBUG:Parsing config...
01/11/13 08:04:20 DEBUG:Parsing commands...
01/11/13 08:04:20 DEBUG:Parsing new individual command.
01/11/13 08:04:20 DEBUG:Setting hostname to localhost and servicename to __host__
01/11/13 08:04:20 DEBUG:Parsing command: check_swap
01/11/13 08:04:20 DEBUG:Command did not contain arguments. Single directive.
01/11/13 08:04:20 DEBUG:Nagios Hostname: localhost -- Nagios Servicename: __host__ -- Command: check_swap -- Arguments: None -- Stdout: None -- Return Code: None
01/11/13 08:04:20 DEBUG:Parsing new individual command.
01/11/13 08:04:20 DEBUG:Setting hostname to localhost and servicename to test
01/11/13 08:04:20 DEBUG:Parsing command: test
01/11/13 08:04:20 DEBUG:Command did not contain arguments. Single directive.
01/11/13 08:04:20 DEBUG:Nagios Hostname: localhost -- Nagios Servicename: test -- Command: test -- Arguments: None -- Stdout: None -- Return Code: None
01/11/13 08:04:20 DEBUG:Parsing new individual command.
01/11/13 08:04:20 DEBUG:Setting hostname to localhost and servicename to cpu usage
01/11/13 08:04:20 DEBUG:Parsing command: check_cpu
01/11/13 08:04:20 DEBUG:Command did not contain arguments. Single directive.
01/11/13 08:04:20 DEBUG:Nagios Hostname: localhost -- Nagios Servicename: cpu usage -- Command: check_cpu -- Arguments: None -- Stdout: None -- Return Code: None
01/11/13 08:04:20 DEBUG:Parsing new individual command.
01/11/13 08:04:20 DEBUG:Setting hostname to localhost and servicename to memory usage
01/11/13 08:04:20 DEBUG:Parsing command: check_memory
01/11/13 08:04:20 DEBUG:Command did not contain arguments. Single directive.
01/11/13 08:04:20 DEBUG:Nagios Hostname: localhost -- Nagios Servicename: memory usage -- Command: check_memory -- Arguments: None -- Stdout: None -- Return Code: None
01/11/13 08:04:20 DEBUG:Establishing Nagios handler...
01/11/13 08:04:20 DEBUG:Nagios handler established.
01/11/13 08:04:20 INFO:Starting new HTTPS connection (1): 192.168.1.54
01/11/13 08:04:20 DEBUG:"GET /nrdp?token=aa&cmd=getconfig&os=chinook&configname=ncpa HTTP/1.1" 301 375
01/11/13 08:04:20 DEBUG:"GET /nrdp/?token=aa&cmd=getconfig&os=chinook&configname=ncpa&token=aa&cmd=getconfig&os=chinook&configname=ncpa HTTP/1.1" 200 1157
01/11/13 08:04:20 DEBUG:hitting url with payload: https://192.168.1.54/nrdp/?token=aa&cmd=getconfig&os=chinook&configname=ncpa&token=aa&cmd=getconfig&os=chinook&configname=ncpa
01/11/13 08:04:20 DEBUG:content response from payload: [listening server]
#~ Declare all IP:Port in a comma separated list
#~ If using passive server, ensure the [passive][connect] directive
#~ is being served.
ipport = 0.0.0.0:5691

[passive]
#~ The IP:Port the passive daemon will connect to get the information, must
#~ be accessible on this machine.
connect = 127.0.0.1:5691
#~ The period of which the checks should be sent out on, in seconds
sleep = 300
#~ Name handlers to kick off on the timer, CSV list, 
#~ must have associated header in the config to parse
handlers = nrdp

[nrdp]
#~ This is the section that the Nagios NRDP handler will use
nrdp_server = https://192.168.1.54/nrdp
nrdp_token = aa

[nrds]
CONFIG_VERSION=0.2
config_os=chinook
config_name=ncpa

[passive checks]
localhost|CPU Usage = check_cpu
localhost|Memory Usage = check_memory
localhost|__HOST__ = check_swap

[logging]
log_level = DEBUG
filename = var/ncpa.log
format = %(asctime)s %(levelname)s:%(message)s
datefmt = %m/%d/%y %H:%M:%S

[plugin suffix instructions]
.vbs = cscript $plugin_name $plugin_args //NoLogo
.ps1 = powershell -ExecutionPolicy Unrestricted $plugin_name $plugin_args
.sh = /bin/sh $plugin_name $plugin_args

01/11/13 08:04:20 DEBUG:URL I am requesting: https://192.168.1.54/nrdp/?token=aa&cmd=getconfig&os=chinook&configname=ncpa&token=aa&cmd=getconfig&os=chinook&configname=ncpa
01/11/13 08:04:20 DEBUG:Content returned: [listening server]
#~ Declare all IP:Port in a comma separated list
#~ If using passive server, ensure the [passive][connect] directive
#~ is being served.
ipport = 0.0.0.0:5691

[passive]
#~ The IP:Port the passive daemon will connect to get the information, must
#~ be accessible on this machine.
connect = 127.0.0.1:5691
#~ The period of which the checks should be sent out on, in seconds
sleep = 300
#~ Name handlers to kick off on the timer, CSV list, 
#~ must have associated header in the config to parse
handlers = nrdp

[nrdp]
#~ This is the section that the Nagios NRDP handler will use
nrdp_server = https://192.168.1.54/nrdp
nrdp_token = aa

[nrds]
CONFIG_VERSION=0.2
config_os=chinook
config_name=ncpa

[passive checks]
localhost|CPU Usage = check_cpu
localhost|Memory Usage = check_memory
localhost|__HOST__ = check_swap

[logging]
log_level = DEBUG
filename = var/ncpa.log
format = %(asctime)s %(levelname)s:%(message)s
datefmt = %m/%d/%y %H:%M:%S

[plugin suffix instructions]
.vbs = cscript $plugin_name $plugin_args //NoLogo
.ps1 = powershell -ExecutionPolicy Unrestricted $plugin_name $plugin_args
.sh = /bin/sh $plugin_name $plugin_args

01/11/13 08:04:20 DEBUG:plugin directives I know about: check_cpu
01/11/13 08:04:20 DEBUG:plugin directives I know about: check_memory
01/11/13 08:04:20 DEBUG:plugin directives I know about: check_swap
01/11/13 08:04:20 DEBUG:plugin directives I know about: test
01/11/13 08:04:20 INFO:Starting new HTTP connection (1): 127.0.0.1
01/11/13 08:04:20 DEBUG:"GET /command?command=enumerate_plugins HTTP/1.1" 301 319
01/11/13 08:04:20 DEBUG:"GET /command/?command=enumerate_plugins&command=enumerate_plugins HTTP/1.1" 200 117
01/11/13 08:04:20 DEBUG:hitting url with payload: http://127.0.0.1:5692/command/?command=enumerate_plugins&command=enumerate_plugins
01/11/13 08:04:20 DEBUG:content response from payload: {"count": 5, "builtins": ["check_memory", "check_swap", "check_cpu"], "externals": ["yancyforprez.sh", "check_nrpe"]}
01/11/13 08:04:20 INFO:Starting new HTTPS connection (1): 192.168.1.54
01/11/13 08:04:20 DEBUG:"GET /nrdp?token=aa&cmd=getplugin&os=Chinook&plugin=test HTTP/1.1" 301 371
01/11/13 08:04:20 DEBUG:"GET /nrdp/?token=aa&cmd=getplugin&os=Chinook&plugin=test&token=aa&cmd=getplugin&os=Chinook&plugin=test HTTP/1.1" 200 23
01/11/13 08:04:20 DEBUG:hitting url with payload: https://192.168.1.54/nrdp/?token=aa&cmd=getplugin&os=Chinook&plugin=test&token=aa&cmd=getplugin&os=Chinook&plugin=test
01/11/13 08:04:20 DEBUG:content response from payload: #!/bin/bash

echo test

01/11/13 08:04:20 DEBUG:downloading plugin to location: plugins/test
