01/10/13 23:41:40 INFO: * Running on http://0.0.0.0:5692/
01/10/13 23:46:23 INFO:192.168.1.28 - - [10/Jan/2013 23:46:23] "GET /command/?command=enumerate_plugins HTTP/1.1" 200 -
01/10/13 23:47:13 INFO:192.168.1.26 - - [10/Jan/2013 23:47:13] "GET /command/?command=enumerate_plugins HTTP/1.0" 200 -
01/10/13 23:50:47 INFO:192.168.1.26 - - [10/Jan/2013 23:50:47] "GET /?command=enumerate_plugins HTTP/1.1" 200 -
01/10/13 23:51:18 INFO:127.0.0.1 - - [10/Jan/2013 23:51:18] "GET /?command=enumerate_plugins HTTP/1.1" 200 -
01/10/13 23:52:28 INFO:127.0.0.1 - - [10/Jan/2013 23:52:28] "GET /?command=enumerate_plugins HTTP/1.1" 200 -
01/11/13 00:01:08 WARNING:User attempted to restart, var/ncpa_listener.pid still exists, exiting.
01/11/13 00:01:15 INFO: * Running on http://0.0.0.0:5692/
01/11/13 00:01:21 ERROR:Exception on /config [GET]
Traceback (most recent call last):
  File "/usr/lib/python2.6/site-packages/flask/app.py", line 1687, in wsgi_app
    response = self.full_dispatch_request()
  File "/usr/lib/python2.6/site-packages/flask/app.py", line 1360, in full_dispatch_request
    rv = self.handle_user_exception(e)
  File "/usr/lib/python2.6/site-packages/flask/app.py", line 1358, in full_dispatch_request
    rv = self.dispatch_request()
  File "/usr/lib/python2.6/site-packages/flask/app.py", line 1344, in dispatch_request
    return self.view_functions[rule.endpoint](**req.view_args)
  File "/tmp/ncpa/agent/listener/server.py", line 36, in config
    logging.exception(e)
NameError: global name 'e' is not defined
01/11/13 00:01:21 INFO:192.168.1.28 - - [11/Jan/2013 00:01:21] "GET /config HTTP/1.1" 500 -
01/11/13 00:01:21 ERROR:Error on request:
Traceback (most recent call last):
  File "/usr/lib/python2.6/site-packages/werkzeug/serving.py", line 159, in run_wsgi
    execute(app)
  File "/usr/lib/python2.6/site-packages/werkzeug/serving.py", line 146, in execute
    application_iter = app(environ, start_response)
  File "/usr/lib/python2.6/site-packages/flask/app.py", line 1701, in __call__
    return self.wsgi_app(environ, start_response)
  File "/usr/lib/python2.6/site-packages/flask/app.py", line 1689, in wsgi_app
    response = self.make_response(self.handle_exception(e))
  File "/usr/lib/python2.6/site-packages/flask/app.py", line 1293, in handle_exception
    return handler(e)
TypeError: error() takes no arguments (1 given)
01/11/13 00:02:26 INFO: * Running on http://0.0.0.0:5692/
01/11/13 00:02:30 ERROR:Exception on /config [GET]
Traceback (most recent call last):
  File "/usr/lib/python2.6/site-packages/flask/app.py", line 1687, in wsgi_app
    response = self.full_dispatch_request()
  File "/usr/lib/python2.6/site-packages/flask/app.py", line 1360, in full_dispatch_request
    rv = self.handle_user_exception(e)
  File "/usr/lib/python2.6/site-packages/flask/app.py", line 1358, in full_dispatch_request
    rv = self.dispatch_request()
  File "/usr/lib/python2.6/site-packages/flask/app.py", line 1344, in dispatch_request
    return self.view_functions[rule.endpoint](**req.view_args)
  File "/tmp/ncpa/agent/listener/server.py", line 38, in config
    logging.exception(e)
NameError: global name 'e' is not defined
01/11/13 00:02:30 INFO:192.168.1.28 - - [11/Jan/2013 00:02:30] "GET /config HTTP/1.1" 500 -
01/11/13 00:02:30 ERROR:Error on request:
Traceback (most recent call last):
  File "/usr/lib/python2.6/site-packages/werkzeug/serving.py", line 159, in run_wsgi
    execute(app)
  File "/usr/lib/python2.6/site-packages/werkzeug/serving.py", line 146, in execute
    application_iter = app(environ, start_response)
  File "/usr/lib/python2.6/site-packages/flask/app.py", line 1701, in __call__
    return self.wsgi_app(environ, start_response)
  File "/usr/lib/python2.6/site-packages/flask/app.py", line 1689, in wsgi_app
    response = self.make_response(self.handle_exception(e))
  File "/usr/lib/python2.6/site-packages/flask/app.py", line 1293, in handle_exception
    return handler(e)
TypeError: error() takes no arguments (1 given)
01/11/13 00:03:58 INFO: * Running on http://0.0.0.0:5692/
01/11/13 00:04:01 ERROR:Exception on /config [GET]
Traceback (most recent call last):
  File "/usr/lib/python2.6/site-packages/flask/app.py", line 1687, in wsgi_app
    response = self.full_dispatch_request()
  File "/usr/lib/python2.6/site-packages/flask/app.py", line 1360, in full_dispatch_request
    rv = self.handle_user_exception(e)
  File "/usr/lib/python2.6/site-packages/flask/app.py", line 1358, in full_dispatch_request
    rv = self.dispatch_request()
  File "/usr/lib/python2.6/site-packages/flask/app.py", line 1344, in dispatch_request
    return self.view_functions[rule.endpoint](**req.view_args)
  File "/tmp/ncpa/agent/listener/server.py", line 38, in config
    logging.exception(e)
NameError: global name 'e' is not defined
01/11/13 00:04:01 INFO:192.168.1.28 - - [11/Jan/2013 00:04:01] "GET /config HTTP/1.1" 500 -
01/11/13 00:04:01 ERROR:Error on request:
Traceback (most recent call last):
  File "/usr/lib/python2.6/site-packages/werkzeug/serving.py", line 159, in run_wsgi
    execute(app)
  File "/usr/lib/python2.6/site-packages/werkzeug/serving.py", line 146, in execute
    application_iter = app(environ, start_response)
  File "/usr/lib/python2.6/site-packages/flask/app.py", line 1701, in __call__
    return self.wsgi_app(environ, start_response)
  File "/usr/lib/python2.6/site-packages/flask/app.py", line 1689, in wsgi_app
    response = self.make_response(self.handle_exception(e))
  File "/usr/lib/python2.6/site-packages/flask/app.py", line 1293, in handle_exception
    return handler(e)
TypeError: error() takes no arguments (1 given)
01/11/13 00:04:22 ERROR:Exception on /config [GET]
Traceback (most recent call last):
  File "/usr/lib/python2.6/site-packages/flask/app.py", line 1687, in wsgi_app
    response = self.full_dispatch_request()
  File "/usr/lib/python2.6/site-packages/flask/app.py", line 1360, in full_dispatch_request
    rv = self.handle_user_exception(e)
  File "/usr/lib/python2.6/site-packages/flask/app.py", line 1358, in full_dispatch_request
    rv = self.dispatch_request()
  File "/usr/lib/python2.6/site-packages/flask/app.py", line 1344, in dispatch_request
    return self.view_functions[rule.endpoint](**req.view_args)
  File "/tmp/ncpa/agent/listener/server.py", line 38, in config
    logging.exception(e)
NameError: global name 'e' is not defined
01/11/13 00:04:22 INFO:192.168.1.28 - - [11/Jan/2013 00:04:22] "GET /config HTTP/1.1" 500 -
01/11/13 00:04:22 ERROR:Error on request:
Traceback (most recent call last):
  File "/usr/lib/python2.6/site-packages/werkzeug/serving.py", line 159, in run_wsgi
    execute(app)
  File "/usr/lib/python2.6/site-packages/werkzeug/serving.py", line 146, in execute
    application_iter = app(environ, start_response)
  File "/usr/lib/python2.6/site-packages/flask/app.py", line 1701, in __call__
    return self.wsgi_app(environ, start_response)
  File "/usr/lib/python2.6/site-packages/flask/app.py", line 1689, in wsgi_app
    response = self.make_response(self.handle_exception(e))
  File "/usr/lib/python2.6/site-packages/flask/app.py", line 1293, in handle_exception
    return handler(e)
TypeError: error() takes no arguments (1 given)
01/11/13 00:06:31 INFO: * Running on http://0.0.0.0:5692/
01/11/13 00:06:37 INFO:192.168.1.28 - - [11/Jan/2013 00:06:37] "GET /command/?command=enumerate_plugins HTTP/1.1" 200 -
01/11/13 00:08:01 INFO:192.168.1.28 - - [11/Jan/2013 00:08:01] "GET /main HTTP/1.1" 404 -
01/11/13 00:08:20 INFO:192.168.1.28 - - [11/Jan/2013 00:08:20] "GET / HTTP/1.1" 200 -
01/11/13 00:08:20 INFO:192.168.1.28 - - [11/Jan/2013 00:08:20] "GET /static/images/ui-bg_flat_75_ffffff_40x100.png HTTP/1.1" 404 -
01/11/13 00:08:20 INFO:192.168.1.28 - - [11/Jan/2013 00:08:20] "GET /static/images/ui-bg_highlight-soft_75_cccccc_1x100.png HTTP/1.1" 404 -
01/11/13 00:08:20 INFO:192.168.1.28 - - [11/Jan/2013 00:08:20] "GET /static/images/ui-bg_glass_75_e6e6e6_1x400.png HTTP/1.1" 404 -
01/11/13 00:08:20 INFO:192.168.1.28 - - [11/Jan/2013 00:08:20] "GET /static/images/ui-bg_glass_65_ffffff_1x400.png HTTP/1.1" 404 -
01/11/13 00:08:20 ERROR:Exception on /config [GET]
Traceback (most recent call last):
  File "/usr/lib/python2.6/site-packages/flask/app.py", line 1687, in wsgi_app
    response = self.full_dispatch_request()
  File "/usr/lib/python2.6/site-packages/flask/app.py", line 1360, in full_dispatch_request
    rv = self.handle_user_exception(e)
  File "/usr/lib/python2.6/site-packages/flask/app.py", line 1358, in full_dispatch_request
    rv = self.dispatch_request()
  File "/usr/lib/python2.6/site-packages/flask/app.py", line 1344, in dispatch_request
    return self.view_functions[rule.endpoint](**req.view_args)
  File "/tmp/ncpa/agent/listener/server.py", line 38, in config
    logging.exception(e)
NameError: global name 'e' is not defined
01/11/13 00:08:20 INFO:192.168.1.28 - - [11/Jan/2013 00:08:20] "GET /config HTTP/1.1" 500 -
01/11/13 00:08:20 ERROR:Error on request:
Traceback (most recent call last):
  File "/usr/lib/python2.6/site-packages/werkzeug/serving.py", line 159, in run_wsgi
    execute(app)
  File "/usr/lib/python2.6/site-packages/werkzeug/serving.py", line 146, in execute
    application_iter = app(environ, start_response)
  File "/usr/lib/python2.6/site-packages/flask/app.py", line 1701, in __call__
    return self.wsgi_app(environ, start_response)
  File "/usr/lib/python2.6/site-packages/flask/app.py", line 1689, in wsgi_app
    response = self.make_response(self.handle_exception(e))
  File "/usr/lib/python2.6/site-packages/flask/app.py", line 1293, in handle_exception
    return handler(e)
TypeError: error() takes no arguments (1 given)
01/11/13 00:08:27 INFO:192.168.1.28 - - [11/Jan/2013 00:08:27] "GET /static/images/ui-bg_glass_75_dadada_1x400.png HTTP/1.1" 404 -
01/11/13 00:08:39 INFO: * Running on http://0.0.0.0:5692/
01/11/13 00:08:43 INFO:192.168.1.28 - - [11/Jan/2013 00:08:43] "GET / HTTP/1.1" 200 -
01/11/13 00:08:44 INFO:192.168.1.28 - - [11/Jan/2013 00:08:44] "GET /static/images/ui-bg_flat_75_ffffff_40x100.png HTTP/1.1" 404 -
01/11/13 00:08:44 INFO:192.168.1.28 - - [11/Jan/2013 00:08:44] "GET /static/images/ui-bg_highlight-soft_75_cccccc_1x100.png HTTP/1.1" 404 -
01/11/13 00:08:44 INFO:192.168.1.28 - - [11/Jan/2013 00:08:44] "GET /static/images/ui-bg_glass_75_e6e6e6_1x400.png HTTP/1.1" 404 -
01/11/13 00:08:44 INFO:192.168.1.28 - - [11/Jan/2013 00:08:44] "GET /static/images/ui-bg_glass_65_ffffff_1x400.png HTTP/1.1" 404 -
01/11/13 00:08:44 ERROR:Exception on /config [GET]
Traceback (most recent call last):
  File "/usr/lib/python2.6/site-packages/flask/app.py", line 1687, in wsgi_app
    response = self.full_dispatch_request()
  File "/usr/lib/python2.6/site-packages/flask/app.py", line 1360, in full_dispatch_request
    rv = self.handle_user_exception(e)
  File "/usr/lib/python2.6/site-packages/flask/app.py", line 1358, in full_dispatch_request
    rv = self.dispatch_request()
  File "/usr/lib/python2.6/site-packages/flask/app.py", line 1344, in dispatch_request
    return self.view_functions[rule.endpoint](**req.view_args)
  File "/tmp/ncpa/agent/listener/server.py", line 37, in config
    logging.exception(e)
NameError: global name 'e' is not defined
01/11/13 00:08:44 INFO:192.168.1.28 - - [11/Jan/2013 00:08:44] "GET /config HTTP/1.1" 500 -
01/11/13 00:08:44 ERROR:Error on request:
Traceback (most recent call last):
  File "/usr/lib/python2.6/site-packages/werkzeug/serving.py", line 159, in run_wsgi
    execute(app)
  File "/usr/lib/python2.6/site-packages/werkzeug/serving.py", line 146, in execute
    application_iter = app(environ, start_response)
  File "/usr/lib/python2.6/site-packages/flask/app.py", line 1701, in __call__
    return self.wsgi_app(environ, start_response)
  File "/usr/lib/python2.6/site-packages/flask/app.py", line 1689, in wsgi_app
    response = self.make_response(self.handle_exception(e))
  File "/usr/lib/python2.6/site-packages/flask/app.py", line 1293, in handle_exception
    return handler(e)
TypeError: error() takes no arguments (1 given)
01/11/13 00:08:49 ERROR:Exception on /config [GET]
Traceback (most recent call last):
  File "/usr/lib/python2.6/site-packages/flask/app.py", line 1687, in wsgi_app
    response = self.full_dispatch_request()
  File "/usr/lib/python2.6/site-packages/flask/app.py", line 1360, in full_dispatch_request
    rv = self.handle_user_exception(e)
  File "/usr/lib/python2.6/site-packages/flask/app.py", line 1358, in full_dispatch_request
    rv = self.dispatch_request()
  File "/usr/lib/python2.6/site-packages/flask/app.py", line 1344, in dispatch_request
    return self.view_functions[rule.endpoint](**req.view_args)
  File "/tmp/ncpa/agent/listener/server.py", line 37, in config
    logging.exception(e)
NameError: global name 'e' is not defined
01/11/13 00:08:49 INFO:192.168.1.28 - - [11/Jan/2013 00:08:49] "GET /config HTTP/1.1" 500 -
01/11/13 00:08:49 ERROR:Error on request:
Traceback (most recent call last):
  File "/usr/lib/python2.6/site-packages/werkzeug/serving.py", line 159, in run_wsgi
    execute(app)
  File "/usr/lib/python2.6/site-packages/werkzeug/serving.py", line 146, in execute
    application_iter = app(environ, start_response)
  File "/usr/lib/python2.6/site-packages/flask/app.py", line 1701, in __call__
    return self.wsgi_app(environ, start_response)
  File "/usr/lib/python2.6/site-packages/flask/app.py", line 1689, in wsgi_app
    response = self.make_response(self.handle_exception(e))
  File "/usr/lib/python2.6/site-packages/flask/app.py", line 1293, in handle_exception
    return handler(e)
TypeError: error() takes no arguments (1 given)
01/11/13 00:09:32 INFO: * Running on http://0.0.0.0:5692/
01/11/13 00:09:36 ERROR:/tmp/ncpa/agent/etc/ncpa.cfg
01/11/13 00:09:36 ERROR:Exception on /config [GET]
Traceback (most recent call last):
  File "/usr/lib/python2.6/site-packages/flask/app.py", line 1687, in wsgi_app
    response = self.full_dispatch_request()
  File "/usr/lib/python2.6/site-packages/flask/app.py", line 1360, in full_dispatch_request
    rv = self.handle_user_exception(e)
  File "/usr/lib/python2.6/site-packages/flask/app.py", line 1358, in full_dispatch_request
    rv = self.dispatch_request()
  File "/usr/lib/python2.6/site-packages/flask/app.py", line 1344, in dispatch_request
    return self.view_functions[rule.endpoint](**req.view_args)
  File "/tmp/ncpa/agent/listener/server.py", line 37, in config
    logging.exception(e)
NameError: global name 'e' is not defined
01/11/13 00:09:36 INFO:192.168.1.28 - - [11/Jan/2013 00:09:36] "GET /config HTTP/1.1" 500 -
01/11/13 00:09:36 ERROR:Error on request:
Traceback (most recent call last):
  File "/usr/lib/python2.6/site-packages/werkzeug/serving.py", line 159, in run_wsgi
    execute(app)
  File "/usr/lib/python2.6/site-packages/werkzeug/serving.py", line 146, in execute
    application_iter = app(environ, start_response)
  File "/usr/lib/python2.6/site-packages/flask/app.py", line 1701, in __call__
    return self.wsgi_app(environ, start_response)
  File "/usr/lib/python2.6/site-packages/flask/app.py", line 1689, in wsgi_app
    response = self.make_response(self.handle_exception(e))
  File "/usr/lib/python2.6/site-packages/flask/app.py", line 1293, in handle_exception
    return handler(e)
TypeError: error() takes no arguments (1 given)
01/11/13 00:11:17 INFO:Starting server...
01/11/13 00:11:17 INFO: * Running on http://0.0.0.0:5692/
01/11/13 00:11:21 ERROR:/tmp/ncpa/agent/etc/ncpa.cfg
01/11/13 00:11:21 ERROR:Exception on /config [GET]
Traceback (most recent call last):
  File "/usr/lib/python2.6/site-packages/flask/app.py", line 1687, in wsgi_app
    response = self.full_dispatch_request()
  File "/usr/lib/python2.6/site-packages/flask/app.py", line 1360, in full_dispatch_request
    rv = self.handle_user_exception(e)
  File "/usr/lib/python2.6/site-packages/flask/app.py", line 1358, in full_dispatch_request
    rv = self.dispatch_request()
  File "/usr/lib/python2.6/site-packages/flask/app.py", line 1344, in dispatch_request
    return self.view_functions[rule.endpoint](**req.view_args)
  File "/tmp/ncpa/agent/listener/server.py", line 37, in config
    logging.exception(e)
NameError: global name 'e' is not defined
01/11/13 00:11:21 INFO:192.168.1.28 - - [11/Jan/2013 00:11:21] "GET /config HTTP/1.1" 500 -
01/11/13 00:11:21 ERROR:Error on request:
Traceback (most recent call last):
  File "/usr/lib/python2.6/site-packages/werkzeug/serving.py", line 159, in run_wsgi
    execute(app)
  File "/usr/lib/python2.6/site-packages/werkzeug/serving.py", line 146, in execute
    application_iter = app(environ, start_response)
  File "/usr/lib/python2.6/site-packages/flask/app.py", line 1701, in __call__
    return self.wsgi_app(environ, start_response)
  File "/usr/lib/python2.6/site-packages/flask/app.py", line 1689, in wsgi_app
    response = self.make_response(self.handle_exception(e))
  File "/usr/lib/python2.6/site-packages/flask/app.py", line 1293, in handle_exception
    return handler(e)
TypeError: error() takes no arguments (1 given)
01/11/13 00:12:36 ERROR:/tmp/ncpa/agent/etc/ncpa.cfg
01/11/13 00:12:36 ERROR:Exception on /config [GET]
Traceback (most recent call last):
  File "/usr/lib/python2.6/site-packages/flask/app.py", line 1687, in wsgi_app
    response = self.full_dispatch_request()
  File "/usr/lib/python2.6/site-packages/flask/app.py", line 1360, in full_dispatch_request
    rv = self.handle_user_exception(e)
  File "/usr/lib/python2.6/site-packages/flask/app.py", line 1358, in full_dispatch_request
    rv = self.dispatch_request()
  File "/usr/lib/python2.6/site-packages/flask/app.py", line 1344, in dispatch_request
    return self.view_functions[rule.endpoint](**req.view_args)
  File "/tmp/ncpa/agent/listener/server.py", line 37, in config
    logging.exception(e)
NameError: global name 'e' is not defined
01/11/13 00:12:36 INFO:192.168.1.28 - - [11/Jan/2013 00:12:36] "GET /config HTTP/1.1" 500 -
01/11/13 00:12:36 ERROR:Error on request:
Traceback (most recent call last):
  File "/usr/lib/python2.6/site-packages/werkzeug/serving.py", line 159, in run_wsgi
    execute(app)
  File "/usr/lib/python2.6/site-packages/werkzeug/serving.py", line 146, in execute
    application_iter = app(environ, start_response)
  File "/usr/lib/python2.6/site-packages/flask/app.py", line 1701, in __call__
    return self.wsgi_app(environ, start_response)
  File "/usr/lib/python2.6/site-packages/flask/app.py", line 1689, in wsgi_app
    response = self.make_response(self.handle_exception(e))
  File "/usr/lib/python2.6/site-packages/flask/app.py", line 1293, in handle_exception
    return handler(e)
TypeError: error() takes no arguments (1 given)
01/11/13 00:13:11 ERROR:/tmp/ncpa/agent/etc/ncpa.cfg
01/11/13 00:13:11 ERROR:Exception on /config [GET]
Traceback (most recent call last):
  File "/usr/lib/python2.6/site-packages/flask/app.py", line 1687, in wsgi_app
    response = self.full_dispatch_request()
  File "/usr/lib/python2.6/site-packages/flask/app.py", line 1360, in full_dispatch_request
    rv = self.handle_user_exception(e)
  File "/usr/lib/python2.6/site-packages/flask/app.py", line 1358, in full_dispatch_request
    rv = self.dispatch_request()
  File "/usr/lib/python2.6/site-packages/flask/app.py", line 1344, in dispatch_request
    return self.view_functions[rule.endpoint](**req.view_args)
  File "/tmp/ncpa/agent/listener/server.py", line 37, in config
    logging.exception(e)
NameError: global name 'e' is not defined
01/11/13 00:13:11 INFO:192.168.1.28 - - [11/Jan/2013 00:13:11] "GET /config HTTP/1.1" 500 -
01/11/13 00:13:11 ERROR:Error on request:
Traceback (most recent call last):
  File "/usr/lib/python2.6/site-packages/werkzeug/serving.py", line 159, in run_wsgi
    execute(app)
  File "/usr/lib/python2.6/site-packages/werkzeug/serving.py", line 146, in execute
    application_iter = app(environ, start_response)
  File "/usr/lib/python2.6/site-packages/flask/app.py", line 1701, in __call__
    return self.wsgi_app(environ, start_response)
  File "/usr/lib/python2.6/site-packages/flask/app.py", line 1689, in wsgi_app
    response = self.make_response(self.handle_exception(e))
  File "/usr/lib/python2.6/site-packages/flask/app.py", line 1293, in handle_exception
    return handler(e)
TypeError: error() takes no arguments (1 given)
01/11/13 00:13:45 ERROR:/tmp/ncpa/agent/etc/ncpa.cfg
01/11/13 00:13:45 ERROR:Exception on /config [GET]
Traceback (most recent call last):
  File "/usr/lib/python2.6/site-packages/flask/app.py", line 1687, in wsgi_app
    response = self.full_dispatch_request()
  File "/usr/lib/python2.6/site-packages/flask/app.py", line 1360, in full_dispatch_request
    rv = self.handle_user_exception(e)
  File "/usr/lib/python2.6/site-packages/flask/app.py", line 1358, in full_dispatch_request
    rv = self.dispatch_request()
  File "/usr/lib/python2.6/site-packages/flask/app.py", line 1344, in dispatch_request
    return self.view_functions[rule.endpoint](**req.view_args)
  File "/tmp/ncpa/agent/listener/server.py", line 37, in config
    params = urllib.urlencode({'msg' : str(e)})
NameError: global name 'e' is not defined
01/11/13 00:13:45 INFO:192.168.1.28 - - [11/Jan/2013 00:13:45] "GET /config HTTP/1.1" 500 -
01/11/13 00:13:45 ERROR:Error on request:
Traceback (most recent call last):
  File "/usr/lib/python2.6/site-packages/werkzeug/serving.py", line 159, in run_wsgi
    execute(app)
  File "/usr/lib/python2.6/site-packages/werkzeug/serving.py", line 146, in execute
    application_iter = app(environ, start_response)
  File "/usr/lib/python2.6/site-packages/flask/app.py", line 1701, in __call__
    return self.wsgi_app(environ, start_response)
  File "/usr/lib/python2.6/site-packages/flask/app.py", line 1689, in wsgi_app
    response = self.make_response(self.handle_exception(e))
  File "/usr/lib/python2.6/site-packages/flask/app.py", line 1293, in handle_exception
    return handler(e)
TypeError: error() takes no arguments (1 given)
01/11/13 00:15:52 INFO:192.168.1.28 - - [11/Jan/2013 00:15:52] "GET /command?command=enumerate_plugins HTTP/1.1" 301 -
01/11/13 00:15:52 INFO:192.168.1.28 - - [11/Jan/2013 00:15:52] "GET /command/?command=enumerate_plugins HTTP/1.1" 200 -
01/11/13 00:16:07 INFO: * Running on http://0.0.0.0:5692/
01/11/13 00:16:09 ERROR:local variable 'externals' referenced before assignment
Traceback (most recent call last):
  File "/tmp/ncpa/agent/listener/commands.py", line 8, in enumerate_plugins
    externals += [x for x in os.listdir('plugins') if os.path.isfile('plugins/%s' % x)]
UnboundLocalError: local variable 'externals' referenced before assignment
01/11/13 00:16:09 INFO:192.168.1.28 - - [11/Jan/2013 00:16:09] "GET /command/?command=enumerate_plugins HTTP/1.1" 200 -
01/11/13 00:16:31 INFO: * Running on http://0.0.0.0:5692/
01/11/13 00:16:32 INFO:192.168.1.28 - - [11/Jan/2013 00:16:32] "GET /command/?command=enumerate_plugins HTTP/1.1" 200 -
